Workbook

Sheet LISEZ-MOI
A1: Wild Side School — modèle de maths (base réutilisable)
A3: Board et features modélisés
A4: • Grille 5 rouleaux × 5 lignes. Gains de 3, 4 ou 5 symboles, de gauche à droite à partir du rouleau 1, payés en x mise totale.
A5: • Mode de gain au choix (Config) : LINES = lignes de paiement de l'onglet Lignes (20 par défaut, meilleur gain par ligne) ou WAYS = 5^5 = 3 125 ways (gain par way).
A6: • 7 symboles payants (Singe, Sac à dos, Basket, Gourde, Pomme, Sifflet, Gomme), 1 symbole bonus (Trophée), 1 symbole spécial (Globe).
A7: • Globe : quand il tombe, les 8 cases autour de lui deviennent des multiplicateurs (valeurs tirées dans l'onglet Multis). Le globe porte lui-même un multi (1x par défaut).
A8: • Free spins : X trophées ou plus déclenchent des FS (table dans Config). Pendant les FS, chaque trophée qui tombe donne +1 FS.
A9: • Bonus buy : achat direct des FS pour un coût en x mise.
A11: Hypothèses à vérifier dans les règles du jeu (tout est réglable dans Config)
A12: • Mode des multiplicateurs (Config) : WILD_ADD = les cases multi sont des wilds, et les multis d'une même way s'additionnent (par défaut). WILD_MULT = wilds, mais les multis se multiplient. GLOBAL_SUM = les multis ne sont pas wild ; la somme des multis à l'écran multiplie le gain total du spin.
A13: • Mode de gain : le vrai mode du jeu n'est pas visible sur les captures. LINES est le réglage par défaut (en WAYS, une grille 5×5 à 7 symboles fait gagner 2 spins sur 3, ce qui est peu réaliste). À vérifier dans les règles du jeu.
A14: • Les trophées et les autres globes ne sont pas remplacés par les multis. Une ligne ou une way 100 % wild paie comme le 1er symbole PAY de la paytable (le Singe).
... A27: Bleu sur fond jaune = saisie · Noir = formule · Vert = lien vers un autre onglet · Fond jaune vif = résultat clé

Sheet Résumé
A1: Résumé du modèle
A2: Analytique = en direct. Simulation = dernière exécution de simulateur.py.
A4: Indicateur | B4: Valeur | C4: Source
A5: RTP cible | B5: =RTP_CIBLE -> 0.96 | C5: Config
A6: Mode de gain | B6: =MODE_GAIN -> LINES | C6: Config
A7: Nombre de lignes / ways | B7: =NB_WAYS -> 20 | C7: Config
A8: Mode des multiplicateurs | B8: =MODE_MULTI -> WILD_ADD | C8: Config
A9: Max win (x mise) | B9: =MAX_WIN -> 5000 | C9: Config
A11: ANALYTIQUE
A12: RTP jeu de base hors globe (exact) | B12: =Calc_Gains!K12 -> 0.26859492 | C12: Calc_Gains
A13: Gain moyen par FS, hors globe (x mise) | B13: =Calc_Gains!K24 -> 0.25010607 | C13: Calc_Gains
A14: Bonus 1 spin sur | B14: =Calc_Bonus!I22 -> 160.96702 | C14: Calc_Bonus
A15: FS moyens par bonus naturel | B15: =Calc_Bonus!I29 -> 24.555628 | C15: Calc_Bonus
A16: FS moyens par bonus buy | B16: =Calc_Bonus!I30 -> 24.118218 | C16: Calc_Bonus
A17: RTP free spins hors globe (estimation) | B17: =IF(ISNUMBER(Calc_Bonus!I29),Calc_Bonus!I21*Calc_Bonus!I29*Calc_Gains!K24,"-") -> 0.03815385 | C17: Calc_Bonus × Calc_Gains
A18: Spins de base avec au moins 1 globe | B18: =Calc_Bonus!I32 -> 0.0041949114 | C18: Calc_Bonus
A19: Spins FS avec au moins 1 globe | B19: =Calc_Bonus!I34 -> 0.028861258 | C19: Calc_Bonus
A20: Multi moyen — base / FS | B20: =TEXT(Multis!D16,"0.00")&"x / "&TEXT(Multis!E16,"0.00")&"x" -> 3.15x / 4.31x | C20: Multis
A22: SIMULATION (globe et multis inclus)
A23: RTP jeu de base | B23: =Simulation!B8 -> 0.52667235 | C23: Simulation
A24: RTP free spins | B24: =Simulation!B9 -> 0.42404572 | C24: Simulation
A25: RTP total | B25: =Simulation!B10 -> 0.95071808 | C25: Simulation
A26: Écart avec la cible | B26: =IF(ISNUMBER(Simulation!B10),Simulation!B10-RTP_CIBLE,"-") -> -0.009281925 | C26: Simulation − cible
A27: Statut | B27: =IF(NOT(ISNUMBER(Simulation!B10)),"Lance le simulateur",IF(ABS(Simulation!B10-RTP_CIBLE)<=MAX(0.002,Simulation!B11),"OK","À ajuster")) -> OK | C27: Tolérance : max(0,2 %, marge d'erreur)
A28: Hit frequency | B28: =Simulation!B12 -> 0.402391 | C28: Simulation
A29: Écart-type par round (volatilité) | B29: =Simulation!B13 -> 13.452326 | C29: Simulation
A30: Bonus 1 spin sur (simulé) | B30: =Simulation!B14 -> 161.39445 | C30: Simulation
A31: Gain moyen bonus naturel (x mise) | B31: =Simulation!B16 -> 68.438626 | C31: Simulation
A32: Gain moyen bonus buy (x mise) | B32: =Simulation!B17 -> 69.285536 | C32: Simulation
A33: RTP du bonus buy au prix actuel | B33: =Simulation!B18 -> 0.96229911 | C33: Simulation
A34: Prix conseillé du bonus buy (x mise) | B34: =IF(ISNUMBER(Simulation!B17),Simulation!B17/RTP_CIBLE,"-") -> 72.172433 | C34: Gain moyen bonus buy / RTP cible
A35: Max win observé (x mise) | B35: =Simulation!B19 -> 4475.7 | C35: Simulation

Sheet Config
A1: Paramètres généraux
A2: Cellules bleues sur fond jaune = à modifier.
A4: Paramètre | B4: Valeur | C4: Notes
A5: Nombre de lignes (hauteur des rouleaux) | B5: 5 | C5: Le tableau binomial de Calc_Bonus va jusqu'à 5 lignes.
A6: Nombre de rouleaux | B6: 5 | C6: Fixe : le modèle est construit pour 5 rouleaux.
A7: Mode de gain | B7: LINES | C7: LINES = lignes de l'onglet Lignes · WAYS = 5^5 ways (gauche → droite).
A8: Nombre de lignes de paiement | B8: =COUNT(Lignes!B5:B54) -> 20 | C8: Calculé depuis l'onglet Lignes (utilisé en mode LINES).
A9: Nombre de façons de gagner | B9: =IF(MODE_GAIN="WAYS",NB_LIGNES^NB_ROULEAUX,NB_PAYLINES) -> 20 | C9: Ways ou lignes selon le mode.
A10: RTP cible | B10: 0.96 | C10: Sert aux contrôles et au prix conseillé du bonus buy.
A11: Max win (x mise) | B11: 5000 | C11: Plafond par round (spin de base + son bonus).
A12: Mode des multiplicateurs | B12: WILD_ADD | C12: WILD_ADD / WILD_MULT / GLOBAL_SUM (voir LISEZ-MOI).
A13: Multi porté par le globe | B13: 1 | C13: Le globe affiche 1x sur la capture.
A14: Trophées minimum pour déclencher les FS | B14: 3 | C14: Doit correspondre à la 1re ligne de la table des FS.
A15: FS ajoutés par trophée pendant les FS | B15: 1 | C15: Retrigger : +1 FS par trophée.
A16: Coût du bonus buy (x mise) | B16: 72 | C16: Prix d'achat des FS.
A17: FS donnés par le bonus buy | B17: 10 | C17: Nombre de FS de départ quand on achète.
A18: Spins de base simulés | B18: 2000000 | C18: Plus c'est grand, plus le RTP simulé est précis.
A19: Sessions de bonus buy simulées | B19: 100000
A20: Graine aléatoire | B20: 12345 | C20: Même graine = mêmes résultats.
A23: Table de déclenchement des free spins
A24: Trophées sur la grille | B24: FS donnés | C24: Notes
A25: 3 | B25: 10
A26: 4 | B26: 12
A27: 5 | B27: 15 | C27: Dernière ligne = « et plus »

Sheet Paytable
A1: Table de paiement (x mise totale, par ligne ou par way)
A2: Types : PAY = symbole payant · SCATTER = trophée bonus · GLOBE = globe à multis. Le 1er PAY est le plus fort.
A3: Code | B3: Symbole | C3: Type | D3: 3 × | E3: 4 × | F3: 5 × | G3: Notes
A4: H1 | B4: Singe | C4: PAY | D4: 1.5 | E4: 5 | F4: 16
A5: H2 | B5: Sac à dos | C5: PAY | D5: 1 | E5: 3.5 | F5: 8
A6: H3 | B6: Basket | C6: PAY | D6: 0.8 | E6: 2.2 | F6: 5.5
A7: M1 | B7: Gourde | C7: PAY | D7: 0.6 | E7: 1.4 | F7: 3.4
A8: L1 | B8: Pomme | C8: PAY | D8: 0.3 | E8: 0.8 | F8: 2.2
A9: L2 | B9: Sifflet | C9: PAY | D9: 0.25 | E9: 0.7 | F9: 1.7
A10: L3 | B10: Gomme | C10: PAY | D10: 0.2 | E10: 0.6 | F10: 1.4
A11: BN | B11: Trophée (bonus) | C11: SCATTER | D11: 0 | E11: 0 | F11: 0 | G11: Ne paie pas : déclenche les FS, +1 FS par trophée pendant les FS.
A12: GL | B12: Globe | C12: GLOBE | D12: 0 | E12: 0 | F12: 0 | G12: Ne paie pas : fait apparaître des multis sur les 8 cases autour.

Sheet Lignes
A1: Lignes de paiement (mode LINES)
A2: Pour chaque ligne : la rangée utilisée sur chaque rouleau (1 = en haut, 5 = en bas). Ligne vide = ignorée. Jusqu'à 50 lignes.
A4: Ligne | B4: R1 | C4: R2 | D4: R3 | E4: R4 | F4: R5 | G4: Aperçu
A5: 1 | B5: 1 | C5: 1 | D5: 1 | E5: 1 | F5: 1 | G5: =IF(COUNT(B5:F5)<5,"",B5&"-"&C5&"-"&D5&"-"&E5&"-"&F5) -> 1-1-1-1-1
A6: 2 | B6: 2 | C6: 2 | D6: 2 | E6: 2 | F6: 2 | G6: =IF(COUNT(B6:F6)<5,"",B6&"-"&C6&"-"&D6&"-"&E6&"-"&F6) -> 2-2-2-2-2
A7: 3 | B7: 3 | C7: 3 | D7: 3 | E7: 3 | F7: 3 | G7: =IF(COUNT(B7:F7)<5,"",B7&"-"&C7&"-"&D7&"-"&E7&"-"&F7) -> 3-3-3-3-3
A8: 4 | B8: 4 | C8: 4 | D8: 4 | E8: 4 | F8: 4 | G8: =IF(COUNT(B8:F8)<5,"",B8&"-"&C8&"-"&D8&"-"&E8&"-"&F8) -> 4-4-4-4-4
A9: 5 | B9: 5 | C9: 5 | D9: 5 | E9: 5 | F9: 5 | G9: =IF(COUNT(B9:F9)<5,"",B9&"-"&C9&"-"&D9&"-"&E9&"-"&F9) -> 5-5-5-5-5
A10: 6 | B10: 1 | C10: 2 | D10: 3 | E10: 2 | F10: 1 | G10: =IF(COUNT(B10:F10)<5,"",B10&"-"&C10&"-"&D10&"-"&E10&"-"&F10) -> 1-2-3-2-1
A11: 7 | B11: 2 | C11: 3 | D11: 4 | E11: 3 | F11: 2 | G11: =IF(COUNT(B11:F11)<5,"",B11&"-"&C11&"-"&D11&"-"&E11&"-"&F11) -> 2-3-4-3-2
A12: 8 | B12: 3 | C12: 4 | D12: 5 | E12: 4 | F12: 3 | G12: =IF(COUNT(B12:F12)<5,"",B12&"-"&C12&"-"&D12&"-"&E12&"-"&F12) -> 3-4-5-4-3
A13: 9 | B13: 5 | C13: 4 | D13: 3 | E13: 4 | F13: 5 | G13: =IF(COUNT(B13:F13)<5,"",B13&"-"&C13&"-"&D13&"-"&E13&"-"&F13) -> 5-4-3-4-5
A14: 10 | B14: 4 | C14: 3 | D14: 2 | E14: 3 | F14: 4 | G14: =IF(COUNT(B14:F14)<5,"",B14&"-"&C14&"-"&D14&"-"&E14&"-"&F14) -> 4-3-2-3-4
A15: 11 | B15: 3 | C15: 2 | D15: 1 | E15: 2 | F15: 3 | G15: =IF(COUNT(B15:F15)<5,"",B15&"-"&C15&"-"&D15&"-"&E15&"-"&F15) -> 3-2-1-2-3
A16: 12 | B16: 1 | C16: 2 | D16: 1 | E16: 2 | F16: 1 | G16: =IF(COUNT(B16:F16)<5,"",B16&"-"&C16&"-"&D16&"-"&E16&"-"&F16) -> 1-2-1-2-1
... A24: 20 | B24: 1 | C24: 3 | D24: 5 | E24: 3 | F24: 1 | G24: =IF(COUNT(B24:F24)<5,"",B24&"-"&C24&"-"&D24&"-"&E24&"-"&F24) -> 1-3-5-3-1
A25: 21 | G25: =IF(COUNT(B25:F25)<5,"",B25&"-"&C25&"-"&D25&"-"&E25&"-"&F25)
A26: 22 | G26: =IF(COUNT(B26:F26)<5,"",B26&"-"&C26&"-"&D26&"-"&E26&"-"&F26)
A27: 23 | G27: =IF(COUNT(B27:F27)<5,"",B27&"-"&C27&"-"&D27&"-"&E27&"-"&F27)
A28: 24 | G28: =IF(COUNT(B28:F28)<5,"",B28&"-"&C28&"-"&D28&"-"&E28&"-"&F28)
A29: 25 | G29: =IF(COUNT(B29:F29)<5,"",B29&"-"&C29&"-"&D29&"-"&E29&"-"&F29)
A30: 26 | G30: =IF(COUNT(B30:F30)<5,"",B30&"-"&C30&"-"&D30&"-"&E30&"-"&F30)
A31: 27 | G31: =IF(COUNT(B31:F31)<5,"",B31&"-"&C31&"-"&D31&"-"&E31&"-"&F31)
A32: 28 | G32: =IF(COUNT(B32:F32)<5,"",B32&"-"&C32&"-"&D32&"-"&E32&"-"&F32)
A33: 29 | G33: =IF(COUNT(B33:F33)<5,"",B33&"-"&C33&"-"&D33&"-"&E33&"-"&F33)
A34: 30 | G34: =IF(COUNT(B34:F34)<5,"",B34&"-"&C34&"-"&D34&"-"&E34&"-"&F34)
A35: 31 | G35: =IF(COUNT(B35:F35)<5,"",B35&"-"&C35&"-"&D35&"-"&E35&"-"&F35)
A36: 32 | G36: =IF(COUNT(B36:F36)<5,"",B36&"-"&C36&"-"&D36&"-"&E36&"-"&F36)
... A54: 50 | G54: =IF(COUNT(B54:F54)<5,"",B54&"-"&C54&"-"&D54&"-"&E54&"-"&F54)

Sheet Poids
A1: Poids des symboles par rouleau
A2: Probabilité d'une case = poids / total du rouleau. À droite : probabilités calculées.
A3: JEU DE BASE
A4: Code | B4: Symbole | C4: R1 | D4: R2 | E4: R3 | F4: R4 | G4: R5 | I4: P(R1) | J4: P(R2) | K4: P(R3) | L4: P(R4) | M4: P(R5)
A5: =Paytable!A4 -> H1 | B5: =Paytable!B4 -> Singe | C5: 300 | D5: 320 | E5: 340 | F5: 360 | G5: 380 | I5: =IF(C$14=0,0,C5/C$14) -> 0.051361068 | J5: =IF(D$14=0,0,D5/D$14) -> 0.054505195 | K5: =IF(E$14=0,0,E5/E$14) -> 0.057325915 | L5: =IF(F$14=0,0,F5/F$14) -> 0.059890201 | M5: =IF(G$14=0,0,G5/G$14) -> 0.062387129
A6: =Paytable!A5 -> H2 | B6: =Paytable!B5 -> Sac à dos | C6: 450 | D6: 460 | E6: 480 | F6: 500 | G6: 520 | I6: =IF(C$14=0,0,C6/C$14) -> 0.077041602 | J6: =IF(D$14=0,0,D6/D$14) -> 0.078351218 | K6: =IF(E$14=0,0,E6/E$14) -> 0.080930703 | L6: =IF(F$14=0,0,F6/F$14) -> 0.083180835 | M6: =IF(G$14=0,0,G6/G$14) -> 0.08537186
A7: =Paytable!A6 -> H3 | B7: =Paytable!B6 -> Basket | C7: 600 | D7: 600 | E7: 620 | F7: 640 | G7: 660 | I7: =IF(C$14=0,0,C7/C$14) -> 0.10272214 | J7: =IF(D$14=0,0,D7/D$14) -> 0.10219724 | K7: =IF(E$14=0,0,E7/E$14) -> 0.10453549 | L7: =IF(F$14=0,0,F7/F$14) -> 0.10647147 | M7: =IF(G$14=0,0,G7/G$14) -> 0.10835659
A8: =Paytable!A7 -> M1 | B8: =Paytable!B7 -> Gourde | C8: 800 | D8: 800 | E8: 800 | F8: 820 | G8: 840 | I8: =IF(C$14=0,0,C8/C$14) -> 0.13696285 | J8: =IF(D$14=0,0,D8/D$14) -> 0.13626299 | K8: =IF(E$14=0,0,E8/E$14) -> 0.13488451 | L8: =IF(F$14=0,0,F8/F$14) -> 0.13641657 | M8: =IF(G$14=0,0,G8/G$14) -> 0.13790839
A9: =Paytable!A8 -> L1 | B9: =Paytable!B8 -> Pomme | C9: 1100 | D9: 1100 | E9: 1100 | F9: 1100 | G9: 1100 | I9: =IF(C$14=0,0,C9/C$14) -> 0.18832392 | J9: =IF(D$14=0,0,D9/D$14) -> 0.18736161 | K9: =IF(E$14=0,0,E9/E$14) -> 0.18546619 | L9: =IF(F$14=0,0,F9/F$14) -> 0.18299784 | M9: =IF(G$14=0,0,G9/G$14) -> 0.18059432
A10: =Paytable!A9 -> L2 | B10: =Paytable!B9 -> Sifflet | C10: 1200 | D10: 1200 | E10: 1200 | F10: 1200 | G10: 1200 | I10: =IF(C$14=0,0,C10/C$14) -> 0.20544427 | J10: =IF(D$14=0,0,D10/D$14) -> 0.20439448 | K10: =IF(E$14=0,0,E10/E$14) -> 0.20232676 | L10: =IF(F$14=0,0,F10/F$14) -> 0.199634 | M10: =IF(G$14=0,0,G10/G$14) -> 0.19701198
A11: =Paytable!A10 -> L3 | B11: =Paytable!B10 -> Gomme | C11: 1300 | D11: 1300 | E11: 1300 | F11: 1300 | G11: 1300 | I11: =IF(C$14=0,0,C11/C$14) -> 0.22256463 | J11: =IF(D$14=0,0,D11/D$14) -> 0.22142735 | K11: =IF(E$14=0,0,E11/E$14) -> 0.21918732 | L11: =IF(F$14=0,0,F11/F$14) -> 0.21627017 | M11: =IF(G$14=0,0,G11/G$14) -> 0.21342965
A12: =Paytable!A11 -> BN | B12: =Paytable!B11 -> Trophée (bonus) | C12: 90 | D12: 90 | E12: 90 | F12: 90 | G12: 90 | I12: =IF(C$14=0,0,C12/C$14) -> 0.01540832 | J12: =IF(D$14=0,0,D12/D$14) -> 0.015329586 | K12: =IF(E$14=0,0,E12/E$14) -> 0.015174507 | L12: =IF(F$14=0,0,F12/F$14) -> 0.01497255 | M12: =IF(G$14=0,0,G12/G$14) -> 0.014775899
A13: =Paytable!A12 -> GL | B13: =Paytable!B12 -> Globe | C13: 1 | D13: 1 | E13: 1 | F13: 1 | G13: 1 | I13: =IF(C$14=0,0,C13/C$14) -> 0.00017120356 | J13: =IF(D$14=0,0,D13/D$14) -> 0.00017032873 | K13: =IF(E$14=0,0,E13/E$14) -> 0.00016860563 | L13: =IF(F$14=0,0,F13/F$14) -> 0.00016636167 | M13: =IF(G$14=0,0,G13/G$14) -> 0.00016417665
B14: Total | C14: =SUM(C5:C13) -> 5841 | D14: =SUM(D5:D13) -> 5871 | E14: =SUM(E5:E13) -> 5931 | F14: =SUM(F5:F13) -> 6011 | G14: =SUM(G5:G13) -> 6091 | I14: =SUM(I5:I13) -> 1 | J14: =SUM(J5:J13) -> 1 | K14: =SUM(K5:K13) -> 1 | L14: =SUM(L5:L13) -> 1 | M14: =SUM(M5:M13) -> 1
A17: FREE SPINS
A18: Code | B18: Symbole | C18: R1 | D18: R2 | E18: R3 | F18: R4 | G18: R5 | I18: P(R1) | J18: P(R2) | K18: P(R3) | L18: P(R4) | M18: P(R5)
A19: =Paytable!A4 -> H1 | B19: =Paytable!B4 -> Singe | C19: 340 | D19: 360 | E19: 380 | F19: 400 | G19: 420 | I19: =IF(C$28=0,0,C19/C$28) -> 0.058249101 | J19: =IF(D$28=0,0,D19/D$28) -> 0.061047991 | K19: =IF(E$28=0,0,E19/E$28) -> 0.063577045 | L19: =IF(F$28=0,0,F19/F$28) -> 0.066039293 | M19: =IF(G$28=0,0,G19/G$28) -> 0.068437347
A20: =Paytable!A5 -> H2 | B20: =Paytable!B5 -> Sac à dos | C20: 480 | D20: 500 | E20: 520 | F20: 540 | G20: 560 | I20: =IF(C$28=0,0,C20/C$28) -> 0.082234024 | J20: =IF(D$28=0,0,D20/D$28) -> 0.084788876 | K20: =IF(E$28=0,0,E20/E$28) -> 0.087000167 | L20: =IF(F$28=0,0,F20/F$28) -> 0.089153046 | M20: =IF(G$28=0,0,G20/G$28) -> 0.091249796
A21: =Paytable!A6 -> H3 | B21: =Paytable!B6 -> Basket | C21: 620 | D21: 640 | E21: 660 | F21: 680 | G21: 700 | I21: =IF(C$28=0,0,C21/C$28) -> 0.10621895 | J21: =IF(D$28=0,0,D21/D$28) -> 0.10852976 | K21: =IF(E$28=0,0,E21/E$28) -> 0.11042329 | L21: =IF(F$28=0,0,F21/F$28) -> 0.1122668 | M21: =IF(G$28=0,0,G21/G$28) -> 0.11406225
A22: =Paytable!A7 -> M1 | B22: =Paytable!B7 -> Gourde | C22: 800 | D22: 800 | E22: 820 | F22: 840 | G22: 860 | I22: =IF(C$28=0,0,C22/C$28) -> 0.13705671 | J22: =IF(D$28=0,0,D22/D$28) -> 0.1356622 | K22: =IF(E$28=0,0,E22/E$28) -> 0.13719257 | L22: =IF(F$28=0,0,F22/F$28) -> 0.13868252 | M22: =IF(G$28=0,0,G22/G$28) -> 0.14013362
A23: =Paytable!A8 -> L1 | B23: =Paytable!B8 -> Pomme | C23: 1050 | D23: 1050 | E23: 1050 | F23: 1050 | G23: 1050 | I23: =IF(C$28=0,0,C23/C$28) -> 0.17988693 | J23: =IF(D$28=0,0,D23/D$28) -> 0.17805664 | K23: =IF(E$28=0,0,E23/E$28) -> 0.17567341 | L23: =IF(F$28=0,0,F23/F$28) -> 0.17335315 | M23: =IF(G$28=0,0,G23/G$28) -> 0.17109337
A24: =Paytable!A9 -> L2 | B24: =Paytable!B9 -> Sifflet | C24: 1150 | D24: 1150 | E24: 1150 | F24: 1150 | G24: 1150 | I24: =IF(C$28=0,0,C24/C$28) -> 0.19701902 | J24: =IF(D$28=0,0,D24/D$28) -> 0.19501441 | K24: =IF(E$28=0,0,E24/E$28) -> 0.19240422 | L24: =IF(F$28=0,0,F24/F$28) -> 0.18986297 | M24: =IF(G$28=0,0,G24/G$28) -> 0.18738797
A25: =Paytable!A10 -> L3 | B25: =Paytable!B10 -> Gomme | C25: 1250 | D25: 1250 | E25: 1250 | F25: 1250 | G25: 1250 | I25: =IF(C$28=0,0,C25/C$28) -> 0.21415111 | J25: =IF(D$28=0,0,D25/D$28) -> 0.21197219 | K25: =IF(E$28=0,0,E25/E$28) -> 0.20913502 | L25: =IF(F$28=0,0,F25/F$28) -> 0.20637279 | M25: =IF(G$28=0,0,G25/G$28) -> 0.20368258
A26: =Paytable!A11 -> BN | B26: =Paytable!B11 -> Trophée (bonus) | C26: 140 | D26: 140 | E26: 140 | F26: 140 | G26: 140 | I26: =IF(C$28=0,0,C26/C$28) -> 0.023984924 | J26: =IF(D$28=0,0,D26/D$28) -> 0.023740885 | K26: =IF(E$28=0,0,E26/E$28) -> 0.023423122 | L26: =IF(F$28=0,0,F26/F$28) -> 0.023113753 | M26: =IF(G$28=0,0,G26/G$28) -> 0.022812449
A27: =Paytable!A12 -> GL | B27: =Paytable!B12 -> Globe | C27: 7 | D27: 7 | E27: 7 | F27: 7 | G27: 7 | I27: =IF(C$28=0,0,C27/C$28) -> 0.0011992462 | J27: =IF(D$28=0,0,D27/D$28) -> 0.0011870443 | K27: =IF(E$28=0,0,E27/E$28) -> 0.0011711561 | L27: =IF(F$28=0,0,F27/F$28) -> 0.0011556876 | M27: =IF(G$28=0,0,G27/G$28) -> 0.0011406225
B28: Total | C28: =SUM(C19:C27) -> 5837 | D28: =SUM(D19:D27) -> 5897 | E28: =SUM(E19:E27) -> 5977 | F28: =SUM(F19:F27) -> 6057 | G28: =SUM(G19:G27) -> 6137 | I28: =SUM(I19:I27) -> 1 | J28: =SUM(J19:J27) -> 1 | K28: =SUM(K19:K27) -> 1 | L28: =SUM(L19:L27) -> 1 | M28: =SUM(M19:M27) -> 1

Sheet Multis
A1: Multiplicateurs qui apparaissent autour du globe
A2: Chaque case voisine d'un globe reçoit une valeur tirée selon ces poids.
A4: Valeur | B4: Poids base | C4: Poids FS | D4: P base | E4: P FS
A5: 2 | B5: 450 | C5: 250 | D5: =IF($B$15=0,0,B5/$B$15) -> 0.45 | E5: =IF($C$15=0,0,C5/$C$15) -> 0.25125628
A6: 3 | B6: 300 | C6: 250 | D6: =IF($B$15=0,0,B6/$B$15) -> 0.3 | E6: =IF($C$15=0,0,C6/$C$15) -> 0.25125628
A7: 4 | B7: 130 | C7: 180 | D7: =IF($B$15=0,0,B7/$B$15) -> 0.13 | E7: =IF($C$15=0,0,C7/$C$15) -> 0.18090452
A8: 5 | B8: 60 | C8: 130 | D8: =IF($B$15=0,0,B8/$B$15) -> 0.06 | E8: =IF($C$15=0,0,C8/$C$15) -> 0.13065327
A9: 6 | B9: 30 | C9: 80 | D9: =IF($B$15=0,0,B9/$B$15) -> 0.03 | E9: =IF($C$15=0,0,C9/$C$15) -> 0.08040201
A10: 8 | B10: 15 | C10: 50 | D10: =IF($B$15=0,0,B10/$B$15) -> 0.015 | E10: =IF($C$15=0,0,C10/$C$15) -> 0.050251256
A11: 10 | B11: 8 | C11: 30 | D11: =IF($B$15=0,0,B11/$B$15) -> 0.008 | E11: =IF($C$15=0,0,C11/$C$15) -> 0.030150754
A12: 15 | B12: 4 | C12: 15 | D12: =IF($B$15=0,0,B12/$B$15) -> 0.004 | E12: =IF($C$15=0,0,C12/$C$15) -> 0.015075377
A13: 20 | B13: 2 | C13: 8 | D13: =IF($B$15=0,0,B13/$B$15) -> 0.002 | E13: =IF($C$15=0,0,C13/$C$15) -> 0.008040201
A14: 50 | B14: 1 | C14: 2 | D14: =IF($B$15=0,0,B14/$B$15) -> 0.001 | E14: =IF($C$15=0,0,C14/$C$15) -> 0.0020100503
A15: Total | B15: =SUM(B5:B14) -> 1000 | C15: =SUM(C5:C14) -> 995 | D15: =SUM(D5:D14) -> 1 | E15: =SUM(E5:E14) -> 1
A16: Multi moyen | D16: =SUMPRODUCT(A5:A14,D5:D14) -> 3.15 | E16: =SUMPRODUCT(A5:A14,E5:E14) -> 4.3065327
A18: La capture montre 5x, 6x et 8x autour d'un globe 1x. Les valeurs et poids sont des valeurs de départ, à ajuster.

Sheet Calc_Gains
A1: RTP des gains — calcul analytique exact HORS globe/multis
A2: WAYS : E[ways de longueur k] = Π(lignes × p_r, r ≤ k) × (1 − p_{k+1})^lignes. LINES : nb lignes × Π(p_r, r ≤ k) × (1 − p_{k+1}). Le globe et ses multis sont ajoutés par le simulateur.
A3: JEU DE BASE — RTP par spin hors globe
A4: Code | B4: Symbole | C4: p R1 | D4: p R2 | E4: p R3 | F4: p R4 | G4: p R5 | H4: E[gains 3] | I4: E[gains 4] | J4: E[gains 5] | K4: RTP (x mise) | L4: % du bloc
A5: =Paytable!A4 -> H1 | B5: =Paytable!B4 -> Singe | C5: =Poids!I5 -> 0.051361068 | D5: =Poids!J5 -> 0.054505195 | E5: =Poids!K5 -> 0.057325915 | F5: =Poids!L5 -> 0.059890201 | G5: =Poids!M5 -> 0.062387129 | H5: =IF(MODE_GAIN="WAYS",NB_LIGNES^3*C5*D5*E5*(1-F5)^NB_LIGNES,NB_PAYLINES*C5*D5*E5*(1-F5)) -> 0.0030173905 | I5: =IF(MODE_GAIN="WAYS",NB_LIGNES^4*C5*D5*E5*F5*(1-G5)^NB_LIGNES,NB_PAYLINES*C5*D5*E5*F5*(1-G5)) -> 0.00018023215 | J5: =IF(MODE_GAIN="WAYS",NB_LIGNES^5,NB_PAYLINES)*C5*D5*E5*F5*G5 -> 1.1992334e-05 | K5: =Paytable!D4*H5+Paytable!E4*I5+Paytable!F4*J5 -> 0.0056191238 | L5: =IF($K$12=0,0,K5/$K$12) -> 0.02092044
A6: =Paytable!A5 -> H2 | B6: =Paytable!B5 -> Sac à dos | C6: =Poids!I6 -> 0.077041602 | D6: =Poids!J6 -> 0.078351218 | E6: =Poids!K6 -> 0.080930703 | F6: =Poids!L6 -> 0.083180835 | G6: =Poids!M6 -> 0.08537186 | H6: =IF(MODE_GAIN="WAYS",NB_LIGNES^3*C6*D6*E6*(1-F6)^NB_LIGNES,NB_PAYLINES*C6*D6*E6*(1-F6)) -> 0.0089577317 | I6: =IF(MODE_GAIN="WAYS",NB_LIGNES^4*C6*D6*E6*F6*(1-G6)^NB_LIGNES,NB_PAYLINES*C6*D6*E6*F6*(1-G6)) -> 0.00074333093 | J6: =IF(MODE_GAIN="WAYS",NB_LIGNES^5,NB_PAYLINES)*C6*D6*E6*F6*G6 -> 6.938289e-05 | K6: =Paytable!D5*H6+Paytable!E5*I6+Paytable!F5*J6 -> 0.012114453 | L6: =IF($K$12=0,0,K6/$K$12) -> 0.045103061
A7: =Paytable!A6 -> H3 | B7: =Paytable!B6 -> Basket | C7: =Poids!I7 -> 0.10272214 | D7: =Poids!J7 -> 0.10219724 | E7: =Poids!K7 -> 0.10453549 | F7: =Poids!L7 -> 0.10647147 | G7: =Poids!M7 -> 0.10835659 | H7: =IF(MODE_GAIN="WAYS",NB_LIGNES^3*C7*D7*E7*(1-F7)^NB_LIGNES,NB_PAYLINES*C7*D7*E7*(1-F7)) -> 0.019611256 | I7: =IF(MODE_GAIN="WAYS",NB_LIGNES^4*C7*D7*E7*F7*(1-G7)^NB_LIGNES,NB_PAYLINES*C7*D7*E7*F7*(1-G7)) -> 0.0020836339 | J7: =IF(MODE_GAIN="WAYS",NB_LIGNES^5,NB_PAYLINES)*C7*D7*E7*F7*G7 -> 0.00025321274 | K7: =Paytable!D6*H7+Paytable!E6*I7+Paytable!F6*J7 -> 0.021665669 | L7: =IF($K$12=0,0,K7/$K$12) -> 0.080662989
A8: =Paytable!A7 -> M1 | B8: =Paytable!B7 -> Gourde | C8: =Poids!I8 -> 0.13696285 | D8: =Poids!J8 -> 0.13626299 | E8: =Poids!K8 -> 0.13488451 | F8: =Poids!L8 -> 0.13641657 | G8: =Poids!M8 -> 0.13790839 | H8: =IF(MODE_GAIN="WAYS",NB_LIGNES^3*C8*D8*E8*(1-F8)^NB_LIGNES,NB_PAYLINES*C8*D8*E8*(1-F8)) -> 0.04347875 | I8: =IF(MODE_GAIN="WAYS",NB_LIGNES^4*C8*D8*E8*F8*(1-G8)^NB_LIGNES,NB_PAYLINES*C8*D8*E8*F8*(1-G8)) -> 0.0059209758 | J8: =IF(MODE_GAIN="WAYS",NB_LIGNES^5,NB_PAYLINES)*C8*D8*E8*F8*G8 -> 0.00094717572 | K8: =Paytable!D7*H8+Paytable!E7*I8+Paytable!F7*J8 -> 0.037597013 | L8: =IF($K$12=0,0,K8/$K$12) -> 0.13997664
A9: =Paytable!A8 -> L1 | B9: =Paytable!B8 -> Pomme | C9: =Poids!I9 -> 0.18832392 | D9: =Poids!J9 -> 0.18736161 | E9: =Poids!K9 -> 0.18546619 | F9: =Poids!L9 -> 0.18299784 | G9: =Poids!M9 -> 0.18059432 | H9: =IF(MODE_GAIN="WAYS",NB_LIGNES^3*C9*D9*E9*(1-F9)^NB_LIGNES,NB_PAYLINES*C9*D9*E9*(1-F9)) -> 0.1069311 | I9: =IF(MODE_GAIN="WAYS",NB_LIGNES^4*C9*D9*E9*F9*(1-G9)^NB_LIGNES,NB_PAYLINES*C9*D9*E9*F9*(1-G9)) -> 0.019625728 | J9: =IF(MODE_GAIN="WAYS",NB_LIGNES^5,NB_PAYLINES)*C9*D9*E9*F9*G9 -> 0.0043254459 | K9: =Paytable!D8*H9+Paytable!E8*I9+Paytable!F8*J9 -> 0.057295894 | L9: =IF($K$12=0,0,K9/$K$12) -> 0.21331712
A10: =Paytable!A9 -> L2 | B10: =Paytable!B9 -> Sifflet | C10: =Poids!I10 -> 0.20544427 | D10: =Poids!J10 -> 0.20439448 | E10: =Poids!K10 -> 0.20232676 | F10: =Poids!L10 -> 0.199634 | G10: =Poids!M10 -> 0.19701198 | H10: =IF(MODE_GAIN="WAYS",NB_LIGNES^3*C10*D10*E10*(1-F10)^NB_LIGNES,NB_PAYLINES*C10*D10*E10*(1-F10)) -> 0.13599882 | I10: =IF(MODE_GAIN="WAYS",NB_LIGNES^4*C10*D10*E10*F10*(1-G10)^NB_LIGNES,NB_PAYLINES*C10*D10*E10*F10*(1-G10)) -> 0.027238934 | J10: =IF(MODE_GAIN="WAYS",NB_LIGNES^5,NB_PAYLINES)*C10*D10*E10*F10*G10 -> 0.0066830343 | K10: =Paytable!D9*H10+Paytable!E9*I10+Paytable!F9*J10 -> 0.064428118 | L10: =IF($K$12=0,0,K10/$K$12) -> 0.23987095
A11: =Paytable!A10 -> L3 | B11: =Paytable!B10 -> Gomme | C11: =Poids!I11 -> 0.22256463 | D11: =Poids!J11 -> 0.22142735 | E11: =Poids!K11 -> 0.21918732 | F11: =Poids!L11 -> 0.21627017 | G11: =Poids!M11 -> 0.21342965 | H11: =IF(MODE_GAIN="WAYS",NB_LIGNES^3*C11*D11*E11*(1-F11)^NB_LIGNES,NB_PAYLINES*C11*D11*E11*(1-F11)) -> 0.16931647 | I11: =IF(MODE_GAIN="WAYS",NB_LIGNES^4*C11*D11*E11*F11*(1-G11)^NB_LIGNES,NB_PAYLINES*C11*D11*E11*F11*(1-G11)) -> 0.03675082 | J11: =IF(MODE_GAIN="WAYS",NB_LIGNES^5,NB_PAYLINES)*C11*D11*E11*F11*G11 -> 0.0099720448 | K11: =Paytable!D10*H11+Paytable!E10*I11+Paytable!F10*J11 -> 0.06987465 | L11: =IF($K$12=0,0,K11/$K$12) -> 0.26014881
B12: Total | H12: =SUM(H5:H11) -> 0.48731153 | I12: =SUM(I5:I11) -> 0.092543655 | J12: =SUM(J5:J11) -> 0.022262289 | K12: =SUM(K5:K11) -> 0.26859492 | L12: =SUM(L5:L11) -> 1
A15: FREE SPINS — gain moyen par FS hors globe (x mise)
A16: Code | B16: Symbole | C16: p R1 | D16: p R2 | E16: p R3 | F16: p R4 | G16: p R5 | H16: E[gains 3] | I16: E[gains 4] | J16: E[gains 5] | K16: RTP (x mise) | L16: % du bloc
A17: =Paytable!A4 -> H1 | B17: =Paytable!B4 -> Singe | C17: =Poids!I19 -> 0.058249101 | D17: =Poids!J19 -> 0.061047991 | E17: =Poids!K19 -> 0.063577045 | F17: =Poids!L19 -> 0.066039293 | G17: =Poids!M19 -> 0.068437347 | H17: =IF(MODE_GAIN="WAYS",NB_LIGNES^3*C17*D17*E17*(1-F17)^NB_LIGNES,NB_PAYLINES*C17*D17*E17*(1-F17)) -> 0.004222985 | I17: =IF(MODE_GAIN="WAYS",NB_LIGNES^4*C17*D17*E17*F17*(1-G17)^NB_LIGNES,NB_PAYLINES*C17*D17*E17*F17*(1-G17)) -> 0.00027816688 | J17: =IF(MODE_GAIN="WAYS",NB_LIGNES^5,NB_PAYLINES)*C17*D17*E17*F17*G17 -> 2.0435559e-05 | K17: =Paytable!D4*H17+Paytable!E4*I17+Paytable!F4*J17 -> 0.0080522808 | L17: =IF($K$24=0,0,K17/$K$24) -> 0.032195464
A18: =Paytable!A5 -> H2 | B18: =Paytable!B5 -> Sac à dos | C18: =Poids!I20 -> 0.082234024 | D18: =Poids!J20 -> 0.084788876 | E18: =Poids!K20 -> 0.087000167 | F18: =Poids!L20 -> 0.089153046 | G18: =Poids!M20 -> 0.091249796 | H18: =IF(MODE_GAIN="WAYS",NB_LIGNES^3*C18*D18*E18*(1-F18)^NB_LIGNES,NB_PAYLINES*C18*D18*E18*(1-F18)) -> 0.011050601 | I18: =IF(MODE_GAIN="WAYS",NB_LIGNES^4*C18*D18*E18*F18*(1-G18)^NB_LIGNES,NB_PAYLINES*C18*D18*E18*F18*(1-G18)) -> 0.00098292688 | J18: =IF(MODE_GAIN="WAYS",NB_LIGNES^5,NB_PAYLINES)*C18*D18*E18*F18*G18 -> 9.8698055e-05 | K18: =Paytable!D5*H18+Paytable!E5*I18+Paytable!F5*J18 -> 0.01528043 | L18: =IF($K$24=0,0,K18/$K$24) -> 0.061095798
A19: =Paytable!A6 -> H3 | B19: =Paytable!B6 -> Basket | C19: =Poids!I21 -> 0.10621895 | D19: =Poids!J21 -> 0.10852976 | E19: =Poids!K21 -> 0.11042329 | F19: =Poids!L21 -> 0.1122668 | G19: =Poids!M21 -> 0.11406225 | H19: =IF(MODE_GAIN="WAYS",NB_LIGNES^3*C19*D19*E19*(1-F19)^NB_LIGNES,NB_PAYLINES*C19*D19*E19*(1-F19)) -> 0.022600809 | I19: =IF(MODE_GAIN="WAYS",NB_LIGNES^4*C19*D19*E19*F19*(1-G19)^NB_LIGNES,NB_PAYLINES*C19*D19*E19*F19*(1-G19)) -> 0.0025321887 | J19: =IF(MODE_GAIN="WAYS",NB_LIGNES^5,NB_PAYLINES)*C19*D19*E19*F19*G19 -> 0.00032601289 | K19: =Paytable!D6*H19+Paytable!E6*I19+Paytable!F6*J19 -> 0.025444533 | L19: =IF($K$24=0,0,K19/$K$24) -> 0.10173497
A20: =Paytable!A7 -> M1 | B20: =Paytable!B7 -> Gourde | C20: =Poids!I22 -> 0.13705671 | D20: =Poids!J22 -> 0.1356622 | E20: =Poids!K22 -> 0.13719257 | F20: =Poids!L22 -> 0.13868252 | G20: =Poids!M22 -> 0.14013362 | H20: =IF(MODE_GAIN="WAYS",NB_LIGNES^3*C20*D20*E20*(1-F20)^NB_LIGNES,NB_PAYLINES*C20*D20*E20*(1-F20)) -> 0.043942323 | I20: =IF(MODE_GAIN="WAYS",NB_LIGNES^4*C20*D20*E20*F20*(1-G20)^NB_LIGNES,NB_PAYLINES*C20*D20*E20*F20*(1-G20)) -> 0.006083765 | J20: =IF(MODE_GAIN="WAYS",NB_LIGNES^5,NB_PAYLINES)*C20*D20*E20*F20*G20 -> 0.00099147961 | K20: =Paytable!D7*H20+Paytable!E7*I20+Paytable!F7*J20 -> 0.038253695 | L20: =IF($K$24=0,0,K20/$K$24) -> 0.15294989
A21: =Paytable!A8 -> L1 | B21: =Paytable!B8 -> Pomme | C21: =Poids!I23 -> 0.17988693 | D21: =Poids!J23 -> 0.17805664 | E21: =Poids!K23 -> 0.17567341 | F21: =Poids!L23 -> 0.17335315 | G21: =Poids!M23 -> 0.17109337 | H21: =IF(MODE_GAIN="WAYS",NB_LIGNES^3*C21*D21*E21*(1-F21)^NB_LIGNES,NB_PAYLINES*C21*D21*E21*(1-F21)) -> 0.093028032 | I21: =IF(MODE_GAIN="WAYS",NB_LIGNES^4*C21*D21*E21*F21*(1-G21)^NB_LIGNES,NB_PAYLINES*C21*D21*E21*F21*(1-G21)) -> 0.016170787 | J21: =IF(MODE_GAIN="WAYS",NB_LIGNES^5,NB_PAYLINES)*C21*D21*E21*F21*G21 -> 0.0033377878 | K21: =Paytable!D8*H21+Paytable!E8*I21+Paytable!F8*J21 -> 0.048188172 | L21: =IF($K$24=0,0,K21/$K$24) -> 0.19267094
A22: =Paytable!A9 -> L2 | B22: =Paytable!B9 -> Sifflet | C22: =Poids!I24 -> 0.19701902 | D22: =Poids!J24 -> 0.19501441 | E22: =Poids!K24 -> 0.19240422 | F22: =Poids!L24 -> 0.18986297 | G22: =Poids!M24 -> 0.18738797 | H22: =IF(MODE_GAIN="WAYS",NB_LIGNES^3*C22*D22*E22*(1-F22)^NB_LIGNES,NB_PAYLINES*C22*D22*E22*(1-F22)) -> 0.11977824 | I22: =IF(MODE_GAIN="WAYS",NB_LIGNES^4*C22*D22*E22*F22*(1-G22)^NB_LIGNES,NB_PAYLINES*C22*D22*E22*F22*(1-G22)) -> 0.022810928 | J22: =IF(MODE_GAIN="WAYS",NB_LIGNES^5,NB_PAYLINES)*C22*D22*E22*F22*G22 -> 0.0052601899 | K22: =Paytable!D9*H22+Paytable!E9*I22+Paytable!F9*J22 -> 0.054854532 | L22: =IF($K$24=0,0,K22/$K$24) -> 0.21932507
A23: =Paytable!A10 -> L3 | B23: =Paytable!B10 -> Gomme | C23: =Poids!I25 -> 0.21415111 | D23: =Poids!J25 -> 0.21197219 | E23: =Poids!K25 -> 0.20913502 | F23: =Poids!L25 -> 0.20637279 | G23: =Poids!M25 -> 0.20368258 | H23: =IF(MODE_GAIN="WAYS",NB_LIGNES^3*C23*D23*E23*(1-F23)^NB_LIGNES,NB_PAYLINES*C23*D23*E23*(1-F23)) -> 0.15068586 | I23: =IF(MODE_GAIN="WAYS",NB_LIGNES^4*C23*D23*E23*F23*(1-G23)^NB_LIGNES,NB_PAYLINES*C23*D23*E23*F23*(1-G23)) -> 0.031202875 | J23: =IF(MODE_GAIN="WAYS",NB_LIGNES^5,NB_PAYLINES)*C23*D23*E23*F23*G23 -> 0.0079810914 | K23: =Paytable!D10*H23+Paytable!E10*I23+Paytable!F10*J23 -> 0.060032425 | L23: =IF($K$24=0,0,K23/$K$24) -> 0.24002786
B24: Total | H24: =SUM(H17:H23) -> 0.44530885 | I24: =SUM(I17:I23) -> 0.080061637 | J24: =SUM(J17:J23) -> 0.018015695 | K24: =SUM(K17:K23) -> 0.25010607 | L24: =SUM(L17:L23) -> 1
A26: Contrôle : mets le poids du Globe à 0 dans Poids, relance le simulateur. Le RTP de base simulé doit être égal au total ci-dessus.

Sheet Calc_Bonus
A1: Fréquence du bonus, nombre de FS, fréquence du globe
A2: Nombre de trophées sur la grille = somme de 5 lois binomiales (une par rouleau), calculée par convolution.
A3: Probabilité d'une case
A4: Symbole / phase | B4: R1 | C4: R2 | D4: R3 | E4: R4 | F4: R5
A5: Trophée — base | B5: =Poids!I12 -> 0.01540832 | C5: =Poids!J12 -> 0.015329586 | D5: =Poids!K12 -> 0.015174507 | E5: =Poids!L12 -> 0.01497255 | F5: =Poids!M12 -> 0.014775899
A6: Trophée — FS | B6: =Poids!I26 -> 0.023984924 | C6: =Poids!J26 -> 0.023740885 | D6: =Poids!K26 -> 0.023423122 | E6: =Poids!L26 -> 0.023113753 | F6: =Poids!M26 -> 0.022812449
A7: Globe — base | B7: =Poids!I13 -> 0.00017120356 | C7: =Poids!J13 -> 0.00017032873 | D7: =Poids!K13 -> 0.00016860563 | E7: =Poids!L13 -> 0.00016636167 | F7: =Poids!M13 -> 0.00016417665
A8: Globe — FS | B8: =Poids!I27 -> 0.0011992462 | C8: =Poids!J27 -> 0.0011870443 | D8: =Poids!K27 -> 0.0011711561 | E8: =Poids!L27 -> 0.0011556876 | F8: =Poids!M27 -> 0.0011406225
A10: Loi du nombre de trophées par rouleau (jeu de base)
A11: k | B11: R1 | C11: R2 | D11: R3 | E11: R4 | F11: R5
A12: 0 | B12: =IF($A12>NB_LIGNES,0,BINOMDIST($A12,NB_LIGNES,B$5,FALSE())) -> 0.92529626 | C12: =IF($A12>NB_LIGNES,0,BINOMDIST($A12,NB_LIGNES,C$5,FALSE())) -> 0.92566628 | D12: =IF($A12>NB_LIGNES,0,BINOMDIST($A12,NB_LIGNES,D$5,FALSE())) -> 0.92639545 | E12: =IF($A12>NB_LIGNES,0,BINOMDIST($A12,NB_LIGNES,E$5,FALSE())) -> 0.92734571 | F12: =IF($A12>NB_LIGNES,0,BINOMDIST($A12,NB_LIGNES,F$5,FALSE())) -> 0.92827176
A13: 1 | B13: =IF($A13>NB_LIGNES,0,BINOMDIST($A13,NB_LIGNES,B$5,FALSE())) -> 0.072401898 | C13: =IF($A13>NB_LIGNES,0,BINOMDIST($A13,NB_LIGNES,C$5,FALSE())) -> 0.072054978 | D13: =IF($A13>NB_LIGNES,0,BINOMDIST($A13,NB_LIGNES,D$5,FALSE())) -> 0.07137099 | E13: =IF($A13>NB_LIGNES,0,BINOMDIST($A13,NB_LIGNES,E$5,FALSE())) -> 0.0704789 | F13: =IF($A13>NB_LIGNES,0,BINOMDIST($A13,NB_LIGNES,F$5,FALSE())) -> 0.06960878
A14: 2 | B14: =IF($A14>NB_LIGNES,0,BINOMDIST($A14,NB_LIGNES,B$5,FALSE())) -> 0.0022661001 | C14: =IF($A14>NB_LIGNES,0,BINOMDIST($A14,NB_LIGNES,C$5,FALSE())) -> 0.0022435385 | D14: =IF($A14>NB_LIGNES,0,BINOMDIST($A14,NB_LIGNES,D$5,FALSE())) -> 0.0021994142 | E14: =IF($A14>NB_LIGNES,0,BINOMDIST($A14,NB_LIGNES,E$5,FALSE())) -> 0.0021425776 | F14: =IF($A14>NB_LIGNES,0,BINOMDIST($A14,NB_LIGNES,F$5,FALSE())) -> 0.0020879154
A15: 3 | B15: =IF($A15>NB_LIGNES,0,BINOMDIST($A15,NB_LIGNES,B$5,FALSE())) -> 3.5463225e-05 | C15: =IF($A15>NB_LIGNES,0,BINOMDIST($A15,NB_LIGNES,C$5,FALSE())) -> 3.4927947e-05 | D15: =IF($A15>NB_LIGNES,0,BINOMDIST($A15,NB_LIGNES,D$5,FALSE())) -> 3.3889278e-05 | E15: =IF($A15>NB_LIGNES,0,BINOMDIST($A15,NB_LIGNES,E$5,FALSE())) -> 3.2567469e-05 | F15: =IF($A15>NB_LIGNES,0,BINOMDIST($A15,NB_LIGNES,F$5,FALSE())) -> 3.1313512e-05
A16: 4 | B16: =IF($A16>NB_LIGNES,0,BINOMDIST($A16,NB_LIGNES,B$5,FALSE())) -> 2.7749003e-07 | C16: =IF($A16>NB_LIGNES,0,BINOMDIST($A16,NB_LIGNES,C$5,FALSE())) -> 2.7188335e-07 | D16: =IF($A16>NB_LIGNES,0,BINOMDIST($A16,NB_LIGNES,D$5,FALSE())) -> 2.6108843e-07 | E16: =IF($A16>NB_LIGNES,0,BINOMDIST($A16,NB_LIGNES,E$5,FALSE())) -> 2.4751497e-07 | F16: =IF($A16>NB_LIGNES,0,BINOMDIST($A16,NB_LIGNES,F$5,FALSE())) -> 2.3481221e-07
A17: 5 | B17: =IF($A17>NB_LIGNES,0,BINOMDIST($A17,NB_LIGNES,B$5,FALSE())) -> 8.6851339e-10 | C17: =IF($A17>NB_LIGNES,0,BINOMDIST($A17,NB_LIGNES,C$5,FALSE())) -> 8.4654909e-10 | D17: =IF($A17>NB_LIGNES,0,BINOMDIST($A17,NB_LIGNES,D$5,FALSE())) -> 8.0458684e-10 | E17: =IF($A17>NB_LIGNES,0,BINOMDIST($A17,NB_LIGNES,E$5,FALSE())) -> 7.5245218e-10 | F17: =IF($A17>NB_LIGNES,0,BINOMDIST($A17,NB_LIGNES,F$5,FALSE())) -> 7.0431924e-10
A19: Convolution : nombre total de trophées sur la grille | H19: Résultats
A20: n | B20: R1 | C20: R1–2 | D20: R1–3 | E20: R1–4 | F20: R1–5 | H20: Indicateur | I20: Valeur
A21: 0 | B21: =B12 -> 0.92529626 | C21: =C$12*B21 -> 0.85651555 | D21: =D$12*C21 -> 0.7934721 | E21: =E$12*D21 -> 0.73582295 | F21: =F$12*E21 -> 0.68304366 | H21: P(déclenchement) par spin | I21: =SUMPRODUCT(--($A$21:$A$46>=SCATTER_MIN),$F$21:$F$46) -> 0.0062124528
A22: 1 | B22: =B13 -> 0.072401898 | C22: =C$12*B22+C$13*B21 -> 0.1336922 | D22: =D$12*C22+D$13*C21 -> 0.18498221 | E22: =E$12*D22+E$13*D21 -> 0.2274655 | F22: =F$12*E22+F$13*E21 -> 0.26236953 | H22: Bonus 1 spin sur | I22: =IF(I21=0,"-",1/I21) -> 160.96702
A23: 2 | B23: =B14 -> 0.0022661001 | C23: =C$12*B23+C$13*B22+C$14*B21 -> 0.0093905074 | D23: =D$12*C23+D$13*C22+D$14*C21 -> 0.0201249 | E23: =E$12*D23+E$13*D22+E$14*D21 -> 0.033400158 | F23: =F$12*E23+F$13*E22+F$14*E21 -> 0.048374355 | H23: ="P(exactement "&Config!A25&" trophées)" -> P(exactement 3 trophées) | I23: =SUMPRODUCT(--($A$21:$A$46=Config!$A$25),$F$21:$F$46) -> 0.0056982029
A24: 3 | B24: =B15 -> 3.5463225e-05 | C24: =C$12*B24+C$13*B23+C$14*B22+C$15*B21 -> 0.00039086605 | D24: =D$12*C24+D$13*C23+D$14*C22+D$15*C21 -> 0.0013553775 | E24: =E$12*D24+E$13*D23+E$14*D22+E$15*D21 -> 0.0030974645 | F24: =F$12*E24+F$13*E23+F$14*E22+F$15*E21 -> 0.0056982029 | H24: ="P(exactement "&Config!A26&" trophées)" -> P(exactement 4 trophées) | I24: =SUMPRODUCT(--($A$21:$A$46=Config!$A$26),$F$21:$F$46) -> 0.00048151781
A25: 4 | B25: =B16 -> 2.7749003e-07 | C25: =C$12*B25+C$13*B24+C$14*B23+C$15*B22+C$16*B21 -> 1.067667e-05 | D25: =D$12*C25+D$13*C24+D$14*C23+D$15*C22+D$16*C21 -> 6.3195289e-05 | E25: =E$12*D25+E$13*D24+E$14*D23+E$15*D22+E$16*D21 -> 0.00020346936 | F25: =F$12*E25+F$13*E24+F$14*E23+F$15*E22+F$16*E21 -> 0.00048151781 | H25: ="P("&Config!A27&" trophées ou plus)" -> P(5 trophées ou plus) | I25: =SUMPRODUCT(--($A$21:$A$46>=Config!$A$27),$F$21:$F$46) -> 3.2732002e-05
A26: 5 | B26: =B17 -> 8.6851339e-10 | C26: =C$12*B26+C$13*B25+C$14*B24+C$15*B23+C$16*B22+C$17*B21 -> 1.9998001e-07 | D26: =D$12*C26+D$13*C25+D$14*C24+D$15*C23+D$16*C22+D$17*C21 -> 2.1607736e-06 | E26: =E$12*D26+E$13*D25+E$14*D24+E$15*D23+E$16*D22+E$17*D21 -> 1.006352e-05 | F26: =F$12*E26+F$13*E25+F$14*E24+F$15*E23+F$16*E22+F$17*E21 -> 3.1071985e-05 | H26: FS initiaux moyens (bonus naturel) | I26: =IF(I21=0,0,(I23*Config!$B$25+I24*Config!$B$26+I25*Config!$B$27)/I21) -> 10.181361
A27: 6 | B27: 0 | C27: =C$13*B26+C$14*B25+C$15*B24+C$16*B23+C$17*B22 -> 2.6012046e-09 | D27: =D$12*C27+D$13*C26+D$14*C25+D$15*C24+D$16*C23+D$17*C22 -> 5.5970423e-08 | E27: =E$12*D27+E$13*D26+E$14*D25+E$15*D24+E$16*D23+E$17*D22 -> 3.8885531e-07 | F27: =F$12*E27+F$13*E26+F$14*E25+F$15*E24+F$16*E23+F$17*E22 -> 1.591295e-06 | H27: Trophées moyens par FS (μ) | I27: =NB_LIGNES*SUM(B6:F6) -> 0.58537566
A28: 7 | B28: 0 | C28: =C$14*B26+C$15*B25+C$16*B24+C$17*B23 -> 2.3200926e-11 | D28: =D$12*C28+D$13*C27+D$14*C26+D$15*C25+D$16*C24+D$17*C23 -> 1.1184134e-09 | E28: =E$12*D28+E$13*D27+E$14*D26+E$15*D25+E$16*D24+E$17*D23 -> 1.2020245e-08 | F28: =F$12*E28+F$13*E27+F$14*E26+F$15*E25+F$16*E24+F$17*E23 -> 6.6359763e-08 | H28: FS ajoutés moyens par FS (μ × FS par trophée) | I28: =I27*FS_PAR_TROPHEE -> 0.58537566
A29: 8 | B29: 0 | C29: =C$15*B26+C$16*B25+C$17*B24 -> 1.3580167e-13 | D29: =D$12*C29+D$13*C28+D$14*C27+D$15*C26+D$16*C25+D$17*C24 -> 1.7382024e-11 | E29: =E$12*D29+E$13*D28+E$14*D27+E$15*D26+E$16*D25+E$17*D24 -> 3.0189723e-10 | F29: =F$12*E29+F$13*E28+F$14*E27+F$15*E26+F$16*E25+F$17*E24 -> 2.2939371e-09 | H29: FS moyens par bonus naturel (avec retrigger) | I29: =IF(I28>=1,"Infini (μ ≥ 1)",I26/(1-I28)) -> 24.555628
A30: 9 | B30: 0 | C30: =C$16*B26+C$17*B25 -> 4.7104326e-16 | D30: =D$12*C30+D$13*C29+D$14*C28+D$15*C27+D$16*C26+D$17*C25 -> 2.1011284e-13 | E30: =E$12*D30+E$13*D29+E$14*D28+E$15*D27+E$16*D26+E$17*D25 -> 6.2213909e-12 | F30: =F$12*E30+F$13*E29+F$14*E28+F$15*E27+F$16*E26+F$17*E25 -> 6.6569864e-11 | H30: FS moyens par bonus buy (avec retrigger) | I30: =IF(I28>=1,"Infini (μ ≥ 1)",BUY_FS/(1-I28)) -> 24.118218
A31: 10 | B31: 0 | C31: =C$17*B26 -> 7.3523921e-19 | D31: =D$12*C31+D$13*C30+D$14*C29+D$15*C28+D$16*C27+D$17*C26 -> 1.9592924e-15 | E31: =E$12*D31+E$13*D30+E$14*D29+E$15*D28+E$16*D27+E$17*D26 -> 1.0577109e-13 | F31: =F$12*E31+F$13*E30+F$14*E29+F$15*E28+F$16*E27+F$17*E26 -> 1.6363756e-12 | H31: Globes moyens par spin — base | I31: =NB_LIGNES*SUM(B7:F7) -> 0.0042033813
A32: 11 | B32: 0 | C32: 0 | D32: =D$13*C31+D$14*C30+D$15*C29+D$16*C28+D$17*C27 -> 1.3841103e-17 | E32: =E$12*D32+E$13*D31+E$14*D30+E$15*D29+E$16*D28+E$17*D27 -> 1.486135e-15 | F32: =F$12*E32+F$13*E31+F$14*E30+F$15*E29+F$16*E28+F$17*E27 -> 3.4281712e-14 | H32: P(au moins 1 globe) — base | I32: =1-(1-B7)^NB_LIGNES*(1-C7)^NB_LIGNES*(1-D7)^NB_LIGNES*(1-E7)^NB_LIGNES*(1-F7)^NB_LIGNES -> 0.0041949114
A33: 12 | B33: 0 | C33: 0 | D33: =D$14*C31+D$15*C30+D$16*C29+D$17*C28 -> 7.1703816e-20 | E33: =E$12*D33+E$13*D32+E$14*D31+E$15*D30+E$16*D29+E$17*D28 -> 1.7226643e-17 | F33: =F$12*E33+F$13*E32+F$14*E31+F$15*E30+F$16*E29+F$17*E28 -> 6.1444898e-16 | H33: Globes moyens par spin — FS | I33: =NB_LIGNES*SUM(B8:F8) -> 0.029268783
A34: 13 | B34: 0 | C34: 0 | D34: =D$15*C31+D$16*C30+D$17*C29 -> 2.5716491e-22 | E34: =E$12*D34+E$13*D33+E$14*D32+E$15*D31+E$16*D30+E$17*D29 -> 1.6384213e-19 | F34: =F$12*E34+F$13*E33+F$14*E32+F$15*E31+F$16*E30+F$17*E29 -> 9.4396946e-18 | H34: P(au moins 1 globe) — FS | I34: =1-(1-B8)^NB_LIGNES*(1-C8)^NB_LIGNES*(1-D8)^NB_LIGNES*(1-E8)^NB_LIGNES*(1-F8)^NB_LIGNES -> 0.028861258
A35: 14 | B35: 0 | C35: 0 | D35: =D$16*C31+D$17*C30 -> 5.7095766e-25 | E35: =E$12*D35+E$13*D34+E$14*D33+E$15*D32+E$16*D31+E$17*D30 -> 1.2661089e-21 | F35: =F$12*E35+F$13*E34+F$14*E33+F$15*E32+F$16*E31+F$17*E30 -> 1.2430221e-19
A36: 15 | B36: 0 | C36: 0 | D36: =D$17*C31 -> 5.915638e-28 | E36: =E$12*D36+E$13*D35+E$14*D34+E$15*D33+E$16*D32+E$17*D31 -> 7.8271506e-24 | F36: =F$12*E36+F$13*E35+F$14*E34+F$15*E33+F$16*E32+F$17*E31 -> 1.4003725e-21 | H36: Retrigger : chaque FS rapporte en moyenne μ×k FS. Nombre moyen de FS = FS initiaux / (1 − μ×k), valable si μ×k < 1.
A37: 16 | B37: 0 | C37: 0 | D37: 0 | E37: =E$13*D36+E$14*D35+E$15*D34+E$16*D33+E$17*D32 -> 3.780276e-26 | F37: =F$12*E37+F$13*E36+F$14*E35+F$15*E34+F$16*E33+F$17*E32 -> 1.344567e-23
A38: 17 | B38: 0 | C38: 0 | D38: 0 | E38: =E$14*D36+E$15*D35+E$16*D34+E$17*D33 -> 1.3746797e-28 | F38: =F$12*E38+F$13*E37+F$14*E36+F$15*E35+F$16*E34+F$17*E33 -> 1.0935295e-25
A39: 18 | B39: 0 | C39: 0 | D39: 0 | E39: =E$15*D36+E$16*D35+E$17*D34 -> 3.540906e-31 | F39: =F$12*E39+F$13*E38+F$14*E37+F$15*E36+F$16*E35+F$17*E34 -> 7.466172e-28
A40: 19 | B40: 0 | C40: 0 | D40: 0 | E40: =E$16*D36+E$17*D35 -> 5.7603923e-34 | F40: =F$12*E40+F$13*E39+F$14*E38+F$15*E37+F$16*E36+F$17*E35 -> 4.2255966e-30
A41: 20 | B41: 0 | C41: 0 | D41: 0 | E41: =E$17*D36 -> 4.4512347e-37 | F41: =F$12*E41+F$13*E40+F$14*E39+F$15*E38+F$16*E37+F$17*E36 -> 1.9473789e-32
A42: 21 | B42: 0 | C42: 0 | D42: 0 | E42: 0 | F42: =F$13*E41+F$14*E40+F$15*E39+F$16*E38+F$17*E37 -> 7.1225895e-35
...

Sheet Simulation
A1: Résultats du simulateur (écrits par simulateur.py — ne pas saisir ici)
A2: Relance : python simulateur.py wild_side_school_math.xlsx
A4: Indicateur | B4: Valeur | F4: Distribution des gains par round | G4: % des rounds
A5: Date de la simulation | B5: 2026-10-09 18:25 | F5: 0 x | G5: 0.597609
A6: Spins de base simulés | B6: 2000000 | F6: 0 – 1 x | G6: 0.3166115
A7: Sessions bonus buy simulées | B7: 100000 | F7: 1 – 5 x | G7: 0.0769695
A8: RTP jeu de base (globe inclus) | B8: 0.52667235 | F8: 5 – 20 x | G8: 0.003793
A9: RTP free spins | B9: 0.42404572 | F9: 20 – 100 x | G9: 0.0026655
A10: RTP total | B10: 0.95071808 | F10: 100 – 1000 x | G10: 0.002339
A11: Marge d'erreur RTP (± à 95 %) | B11: 0.018643973 | F11: 1000 x – max win | G11: 1.25e-05
A12: Hit frequency | B12: 0.402391 | F12: Max win atteint | G12: 0
A13: Écart-type par round (x mise) | B13: 13.452326
A14: Bonus 1 spin sur | B14: 161.39445
A15: FS moyens par bonus naturel | B15: 24.533167
A16: Gain moyen bonus naturel (x mise) | B16: 68.438626
A17: Gain moyen bonus buy (x mise) | B17: 69.285536
A18: RTP du bonus buy | B18: 0.96229911
A19: Max win observé — jeu (x mise) | B19: 4475.7
A20: Max win observé — bonus buy (x mise) | B20: 5000
A21: Spins de base avec au moins 1 globe | B21: 0.004152
A22: RTP apporté par les spins de base avec globe | B22: 0.2591201
A25: RTP par symbole (x mise par spin de base)
A26: Code | B26: Symbole | C26: Jeu de base | D26: Free spins
A27: H1 | B27: Singe | C27: 0.092497 | D27: 0.139397
A28: H2 | B28: Sac à dos | C28: 0.05200775 | D28: 0.06428875
A29: H3 | B29: Basket | C29: 0.06072895 | D29: 0.0596361
A30: M1 | B30: Gourde | C30: 0.0639165 | D30: 0.0455474
A31: L1 | B31: Pomme | C31: 0.08221105 | D31: 0.04133085
A32: L2 | B32: Sifflet | C32: 0.08686 | D32: 0.039511125
A33: L3 | B33: Gomme | C33: 0.0884511 | D33: 0.0343345
