Workbook
Name NB_LIGNES: Config!$B$5
Name NB_ROULEAUX: Config!$B$6
Name MODE_GAIN: Config!$B$7
Name CASCADES: Config!$B$8
Name NB_PAYLINES: Config!$B$9
Name NB_WAYS: Config!$B$10
Name RTP_CIBLE: Config!$B$11
Name MAX_WIN: Config!$B$12
Name MODE_MULTI: Config!$B$13
Name MULTI_GLOBE: Config!$B$14
Name FS_PAR_BONUS: Config!$B$15
Name BOOST_COUT: Config!$B$16
Name SIM_SPINS: Config!$B$17
Name SIM_BOOST: Config!$B$18
Name SIM_BUY: Config!$B$19
Name SIM_SEED: Config!$B$20
Name BONUS: Config!$A$25:$E$27
Name PAYTABLE: Paytable!$A$4:$F$12
Name TAILLES_CLUSTER: Paytable!$C$16:$J$16
Name PAYTABLE_CLUSTER: Paytable!$C$18:$J$26
Name LIGNES: Lignes!$B$5:$F$54
Name POIDS_BASE: Poids!$A$5:$G$13
Name POIDS_BOOST: Poids!$A$19:$G$27
Name POIDS_FS1: Poids!$A$33:$G$41
Name POIDS_FS2: Poids!$A$47:$G$55
Name POIDS_FS3: Poids!$A$61:$G$69
Name MULTIS: Multis!$A$5:$E$13

Sheet LISEZ-MOI
A1: Modèle de maths : grille 5×5, clusters, globe à multiplicateurs, free spins
A3: Le principe
A4: • Grille 5 rouleaux × 5 lignes, gains en CLUSTERS : un groupe d'au moins 5 symboles identiques reliés horizontalement ou verticalement paie selon sa taille (paytable cluster).
A5: • Cascades : les clusters gagnants explosent, les symboles au-dessus tombent et de nouveaux arrivent, jusqu'à ce qu'il n'y ait plus de gain (réglable dans Config).
A6: • Globe : quand il arrive sur la grille (au départ ou pendant une cascade), les 8 cases autour de lui deviennent des multiplicateurs (valeurs dans l'onglet Multis). Le globe porte lui-même un multi (1x par défaut).
A7: • 3 bonus (table dans Config) : 3 symboles bonus = bonus 1, 4 = bonus 2, 5 = bonus 3, le bonus caché (globe garanti à chaque free spin). Chaque bonus a ses propres poids (onglet Poids) et ses multis (onglet Multis). Pendant les FS, chaque symbole bonus donne +1 FS.
A8: • Spins boostés : un spin plus cher (BOOST_COUT x la mise) avec plus de symboles bonus sur les rouleaux, donc des bonus plus fréquents. Bonus buy : achat direct d'un bonus au prix de la table.
A9: • Symboles génériques (Premium 1-3, Moyen 1, Bas 1-3, Bonus, Globe) : la direction artistique se fait à part, les maths ne changent pas.
A11: Règles des multiplicateurs (Config, alignées sur le math SDK de Stake Engine)
A12: • WILD_ADD (par défaut) : les cases multi et le globe sont des wilds. Ils relient les symboles d'un cluster ; le multi du cluster est la somme des multis qu'il contient (globe 1x compris), 1 si aucun.
A13: • GLOBAL_SUM : les multis ne sont pas wild ; la somme de tous les multis à l'écran multiplie chaque gain.
A14: • Les symboles bonus et les autres globes ne sont pas remplacés par les multis. Au départ, au plus 1 symbole bonus par rouleau (comme sur les bandes du SDK).
... A27: Bleu sur fond jaune = saisie · Noir = formule · Vert = lien vers un autre onglet · Fond jaune vif = résultat clé

Sheet Résumé
A1: Résumé du modèle
A2: Analytique = en direct. Simulation = dernière exécution de simulateur.py.
A4: Indicateur | B4: Jeu de base | C4: Spins boostés | D4: Source
A5: RTP cible | B5: =RTP_CIBLE | C5: =RTP_CIBLE | D5: Config
A6: Prix d'un spin (x mise) | B6: =1 | C6: =BOOST_COUT | D6: Config
A7: Mode de gain | B7: =MODE_GAIN | D7: Config
A8: Mode des multiplicateurs | B8: =MODE_MULTI | D8: Config
A9: Max win (x mise) | B9: =MAX_WIN | D9: Config
A11: ANALYTIQUE (grille de départ, sans cascades)
A12: ="Bonus 1 ("&Config!A25&") : 1 spin sur" | B12: =Calc_Bonus!B27 | C12: =Calc_Bonus!C27 | D12: Calc_Bonus
A13: ="Bonus 2 ("&Config!A26&") : 1 spin sur" | B13: =Calc_Bonus!B28 | C13: =Calc_Bonus!C28 | D13: Calc_Bonus
A14: ="Bonus 3 ("&Config!A27&") : 1 spin sur" | B14: =Calc_Bonus!B29 | C14: =Calc_Bonus!C29 | D14: Calc_Bonus
A15: Tous les bonus : 1 spin sur | B15: =Calc_Bonus!B30 | C15: =Calc_Bonus!C30 | D15: Calc_Bonus
A16: Spins avec au moins 1 globe | B16: =Calc_Bonus!C34 | C16: =Calc_Bonus!C35 | D16: Calc_Bonus
A17: RTP jeu de base hors globe (LINES / WAYS) | B17: =IF(MODE_GAIN="CLUSTER","voir simulation",Calc_Gains!K12) | D17: Calc_Gains
A19: SIMULATION (globe, multis et cascades inclus)
A20: RTP des spins (hors bonus) | B20: =Simulation!B8 | C20: =Simulation!C8 | D20: Simulation
A21: RTP des bonus | B21: =Simulation!B9 | C21: =Simulation!C9 | D21: Simulation
A22: RTP total | B22: =Simulation!B10 | C22: =Simulation!C10 | D22: Simulation
A23: Statut | B23: =IF(NOT(ISNUMBER(Simulation!B10)),"Lance le simulateur",IF(ABS(Simulation!B10-RTP_CIBLE)<=MAX(0.002,Simulation!B11),"OK","À ajuster")) | C23: =IF(NOT(ISNUMBER(Simulation!C10)),"Lance le simulateur",IF(ABS(Simulation!C10-RTP_CIBLE)<=MAX(0.002,Simulation!C11),"OK","À ajuster")) | D23: Tolérance : max(0,2 %, marge d'erreur)
A24: Hit frequency | B24: =Simulation!B12 | C24: =Simulation!C12 | D24: Simulation
A25: Écart-type par tour (volatilité, x mise) | B25: =Simulation!B13 | C25: =Simulation!C13 | D25: Simulation
A26: Tous les bonus : 1 spin sur (cascades comprises) | B26: =Simulation!B14 | C26: =Simulation!C14 | D26: Simulation
A27: ="Bonus 1 : 1 spin sur / gain moyen" | B27: =IF(ISNUMBER(Simulation!B15),TEXT(Simulation!B15,"# ##0")&" / "&TEXT(Simulation!B18,"0.0")&"x","-") | C27: =IF(ISNUMBER(Simulation!C15),TEXT(Simulation!C15,"# ##0")&" / "&TEXT(Simulation!C18,"0.0")&"x","-") | D27: Simulation
A28: ="Bonus 2 : 1 spin sur / gain moyen" | B28: =IF(ISNUMBER(Simulation!B16),TEXT(Simulation!B16,"# ##0")&" / "&TEXT(Simulation!B19,"0.0")&"x","-") | C28: =IF(ISNUMBER(Simulation!C16),TEXT(Simulation!C16,"# ##0")&" / "&TEXT(Simulation!C19,"0.0")&"x","-") | D28: Simulation
A29: ="Bonus 3 : 1 spin sur / gain moyen" | B29: =IF(ISNUMBER(Simulation!B17),TEXT(Simulation!B17,"# ##0")&" / "&TEXT(Simulation!B20,"0.0")&"x","-") | C29: =IF(ISNUMBER(Simulation!C17),TEXT(Simulation!C17,"# ##0")&" / "&TEXT(Simulation!C20,"0.0")&"x","-") | D29: Simulation
A30: 3 étoiles : etl40b (limite 0,9) | B30: =Simulation!B26 | C30: =Simulation!C26 | D30: Simulation
A31: 3 étoiles : etl10k (limite 0,8) | B31: =Simulation!B27 | C31: =Simulation!C27 | D31: Simulation
A32: Max win observé (x mise) | B32: =Simulation!B24 | C32: =Simulation!C24 | D32: Simulation
A34: BONUS BUY (chaque bonus joué directement)
A35: ="Bonus 1 ("&Config!A25&") : prix / gain moyen / RTP" | B35: =IF(ISNUMBER(Simulation!B42),TEXT(Simulation!B42,"0")&"x / ","non achetable / ")&IF(ISNUMBER(Simulation!B43),TEXT(Simulation!B43,"0.0")&"x","-")&IF(ISNUMBER(Simulation!B44)," / "&TEXT(Simulation!B44,"0.00%"),"") | D35: Simulation
A36: ="Bonus 1 : prix conseillé (gain moyen / RTP cible)" | B36: =Simulation!B45 | D36: Simulation
A37: ="Bonus 2 ("&Config!A26&") : prix / gain moyen / RTP" | B37: =IF(ISNUMBER(Simulation!C42),TEXT(Simulation!C42,"0")&"x / ","non achetable / ")&IF(ISNUMBER(Simulation!C43),TEXT(Simulation!C43,"0.0")&"x","-")&IF(ISNUMBER(Simulation!C44)," / "&TEXT(Simulation!C44,"0.00%"),"") | D37: Simulation
A38: ="Bonus 2 : prix conseillé (gain moyen / RTP cible)" | B38: =Simulation!C45 | D38: Simulation
A39: ="Bonus 3 ("&Config!A27&") : prix / gain moyen / RTP" | B39: =IF(ISNUMBER(Simulation!D42),TEXT(Simulation!D42,"0")&"x / ","non achetable / ")&IF(ISNUMBER(Simulation!D43),TEXT(Simulation!D43,"0.0")&"x","-")&IF(ISNUMBER(Simulation!D44)," / "&TEXT(Simulation!D44,"0.00%"),"") | D39: Simulation
A40: ="Bonus 3 : prix conseillé (gain moyen / RTP cible)" | B40: =Simulation!D45 | D40: Simulation

Sheet Config
A1: Paramètres généraux
A2: Cellules bleues sur fond jaune = à modifier.
A4: Paramètre | B4: Valeur | C4: Notes
A5: Nombre de lignes (hauteur des rouleaux) | B5: 5 | C5: Le tableau binomial de Calc_Bonus va jusqu'à 5 lignes.
A6: Nombre de rouleaux | B6: 5 | C6: Fixe : le modèle est construit pour 5 rouleaux.
A7: Mode de gain | B7: CLUSTER | C7: CLUSTER = groupes reliés (paytable cluster) · LINES = lignes de l'onglet Lignes · WAYS = 5^5 ways.
A8: Cascades (mode CLUSTER) | B8: OUI | C8: OUI = les clusters gagnants explosent et de nouveaux symboles tombent, jusqu'à ce qu'il n'y ait plus de gain.
A9: Nombre de lignes de paiement | B9: =COUNT(Lignes!B5:B54) | C9: Calculé depuis l'onglet Lignes (utilisé en mode LINES).
A10: Lignes / ways / cases | B10: =IF(MODE_GAIN="WAYS",NB_LIGNES^NB_ROULEAUX,IF(MODE_GAIN="LINES",NB_PAYLINES,NB_LIGNES*NB_ROULEAUX)) | C10: Ways, lignes, ou nombre de cases (CLUSTER) selon le mode.
A11: RTP cible | B11: 0.96 | C11: Sert aux contrôles et au prix conseillé du bonus buy.
A12: Max win (x mise) | B12: 10000 | C12: Plafond par round (spin de base + son bonus). Entre 10 000 et 15 000 pour Stake.
A13: Mode des multiplicateurs | B13: WILD_ADD | C13: WILD_ADD / WILD_MULT / GLOBAL_SUM (voir LISEZ-MOI).
A14: Multi porté par le globe | B14: 1 | C14: Le globe affiche 1x sur la capture.
A15: FS ajoutés par symbole bonus pendant les FS | B15: 1 | C15: Retrigger : +1 FS par symbole bonus, dans les 3 bonus.
A16: Prix d'un spin boosté (x mise) | B16: 1.25 | C16: Spins boostés : bandes « SPINS BOOSTÉS » de l'onglet Poids (plus de symboles bonus).
A17: Spins de base simulés | B17: 3000000 | C17: Plus c'est grand, plus le RTP simulé est précis.
A18: Spins boostés simulés | B18: 1500000 | C18: 0 = pas de simulation des spins boostés.
A19: Tours simulés par bonus (comme un achat) | B19: 100000 | C19: Pour le prix des bonus buy et les stats de chaque bonus.
A20: Graine aléatoire | B20: 12345 | C20: Même graine = mêmes résultats.
A23: Les 3 bonus
A24: Bonus 1, 2, 3 (nom libre) | B24: Symboles bonus | C24: FS donnés | D24: Globe garanti à chaque FS | E24: Prix d'achat (x mise) | F24: Notes
A25: Free spins | B25: 3 | C25: 10 | D25: NON | E25: 59 | F25: Déclenché par 3 symboles bonus sur la grille finale (après cascades). Poids et multis : colonnes « Bonus 1 ».
A26: Super free spins | B26: 4 | C26: 12 | D26: NON | E26: 160 | F26: 4 symboles bonus. Plus de globes et des multis plus forts (Poids / Multis « Bonus 2 »).
A27: Bonus caché | B27: 5 | C27: 5 | D27: OUI | F27: 5 symboles bonus ou plus : le bonus caché. Peu de FS, mais un globe garanti sur chaque FS. Prix vide = non achetable.
A28: Le bonus déclenché est le plus fort dont le nombre de symboles bonus est atteint. Les nombres doivent être croissants (5 au plus : 1 symbole bonus maximum par rouleau au départ).

Sheet Paytable
A1: Tables de paiement (x mise totale)
A2: Types : PAY = symbole payant · SCATTER = symbole bonus bonus · GLOBE = globe à multis. Le 1er PAY est le plus fort.
A3: Code | B3: Symbole | C3: Type | D3: 3 × | E3: 4 × | F3: 5 × | G3: Notes (LINES / WAYS : gain par ligne ou par way)
A4: H1 | B4: Premium 1 | C4: PAY | D4: 1.5 | E4: 5 | F4: 16
A5: H2 | B5: Premium 2 | C5: PAY | D5: 1 | E5: 3.5 | F5: 8
A6: H3 | B6: Premium 3 | C6: PAY | D6: 0.8 | E6: 2.2 | F6: 5.5
A7: M1 | B7: Moyen 1 | C7: PAY | D7: 0.6 | E7: 1.4 | F7: 3.4
A8: L1 | B8: Bas 1 | C8: PAY | D8: 0.3 | E8: 0.8 | F8: 2.2
A9: L2 | B9: Bas 2 | C9: PAY | D9: 0.25 | E9: 0.7 | F9: 1.7
A10: L3 | B10: Bas 3 | C10: PAY | D10: 0.2 | E10: 0.6 | F10: 1.4
A11: BN | B11: Bonus (scatter) | C11: SCATTER | D11: 0 | E11: 0 | F11: 0 | G11: Ne paie pas : déclenche les FS, +1 FS par symbole bonus pendant les FS.
A12: GL | B12: Globe (spécial) | C12: GLOBE | D12: 0 | E12: 0 | F12: 0 | G12: Ne paie pas : fait apparaître des multis sur les 8 cases autour.
A15: PAYTABLE CLUSTER (mode CLUSTER) : gain d'un cluster selon sa taille, x mise totale
A16: Taille mini → | B16: Chaque colonne paie de sa taille jusqu'à la suivante − 1 ; la dernière jusqu'à 25. | C16: 5 | D16: 6 | E16: 7 | F16: 8 | G16: 9 | H16: 11 | I16: 13 | J16: 16
A17: Code | B17: Symbole | C17: =IF(C16="","",C16&IF(D16="","+",IF(D16-1=C16,"","–"&(D16-1)))) | D17: =IF(D16="","",D16&IF(E16="","+",IF(E16-1=D16,"","–"&(E16-1)))) | E17: =IF(E16="","",E16&IF(F16="","+",IF(F16-1=E16,"","–"&(F16-1)))) | F17: =IF(F16="","",F16&IF(G16="","+",IF(G16-1=F16,"","–"&(G16-1)))) | G17: =IF(G16="","",G16&IF(H16="","+",IF(H16-1=G16,"","–"&(H16-1)))) | H17: =IF(H16="","",H16&IF(I16="","+",IF(I16-1=H16,"","–"&(I16-1)))) | I17: =IF(I16="","",I16&IF(J16="","+",IF(J16-1=I16,"","–"&(J16-1)))) | J17: =J16&"+"
A18: =A4 | B18: =B4 | C18: 2.5 | D18: 3.5 | E18: 5 | F18: 7 | G18: 12 | H18: 25 | I18: 60 | J18: 180
A19: =A5 | B19: =B5 | C19: 1.8 | D19: 2.5 | E19: 3.5 | F19: 5 | G19: 8 | H19: 18 | I19: 40 | J19: 120
A20: =A6 | B20: =B6 | C20: 1.2 | D20: 1.8 | E20: 2.5 | F20: 3.5 | G20: 6 | H20: 12 | I20: 30 | J20: 90
A21: =A7 | B21: =B7 | C21: 1 | D21: 1.2 | E21: 1.8 | F21: 2.5 | G21: 5 | H21: 10 | I21: 25 | J21: 60
A22: =A8 | B22: =B8 | C22: 0.6 | D22: 0.8 | E22: 1.2 | F22: 1.8 | G22: 3.5 | H22: 7 | I22: 18 | J22: 50
A23: =A9 | B23: =B9 | C23: 0.5 | D23: 0.7 | E23: 1 | F23: 1.5 | G23: 3 | H23: 6 | I23: 15 | J23: 35
A24: =A10 | B24: =B10 | C24: 0.4 | D24: 0.6 | E24: 0.8 | F24: 1.2 | G24: 2.5 | H24: 5 | I24: 12 | J24: 30
A25: =A11 | B25: =B11 | C25: 0 | D25: 0 | E25: 0 | F25: 0 | G25: 0 | H25: 0 | I25: 0 | J25: 0
A26: =A12 | B26: =B12 | C26: 0 | D26: 0 | E26: 0 | F26: 0 | G26: 0 | H26: 0 | I26: 0 | J26: 0
A28: Le tableau du haut (3/4/5 ×) sert aux modes LINES et WAYS ; celui-ci au mode CLUSTER. Garde le même ordre de symboles partout.

Sheet Lignes
A1: Lignes de paiement (mode LINES)
A2: Pour chaque ligne : la rangée utilisée sur chaque rouleau (1 = en haut, 5 = en bas). Ligne vide = ignorée. Jusqu'à 50 lignes.
A4: Ligne | B4: R1 | C4: R2 | D4: R3 | E4: R4 | F4: R5 | G4: Aperçu
A5: 1 | B5: 1 | C5: 1 | D5: 1 | E5: 1 | F5: 1 | G5: =IF(COUNT(B5:F5)<5,"",B5&"-"&C5&"-"&D5&"-"&E5&"-"&F5)
A6: 2 | B6: 2 | C6: 2 | D6: 2 | E6: 2 | F6: 2 | G6: =IF(COUNT(B6:F6)<5,"",B6&"-"&C6&"-"&D6&"-"&E6&"-"&F6)
A7: 3 | B7: 3 | C7: 3 | D7: 3 | E7: 3 | F7: 3 | G7: =IF(COUNT(B7:F7)<5,"",B7&"-"&C7&"-"&D7&"-"&E7&"-"&F7)
A8: 4 | B8: 4 | C8: 4 | D8: 4 | E8: 4 | F8: 4 | G8: =IF(COUNT(B8:F8)<5,"",B8&"-"&C8&"-"&D8&"-"&E8&"-"&F8)
A9: 5 | B9: 5 | C9: 5 | D9: 5 | E9: 5 | F9: 5 | G9: =IF(COUNT(B9:F9)<5,"",B9&"-"&C9&"-"&D9&"-"&E9&"-"&F9)
A10: 6 | B10: 1 | C10: 2 | D10: 3 | E10: 2 | F10: 1 | G10: =IF(COUNT(B10:F10)<5,"",B10&"-"&C10&"-"&D10&"-"&E10&"-"&F10)
A11: 7 | B11: 2 | C11: 3 | D11: 4 | E11: 3 | F11: 2 | G11: =IF(COUNT(B11:F11)<5,"",B11&"-"&C11&"-"&D11&"-"&E11&"-"&F11)
A12: 8 | B12: 3 | C12: 4 | D12: 5 | E12: 4 | F12: 3 | G12: =IF(COUNT(B12:F12)<5,"",B12&"-"&C12&"-"&D12&"-"&E12&"-"&F12)
A13: 9 | B13: 5 | C13: 4 | D13: 3 | E13: 4 | F13: 5 | G13: =IF(COUNT(B13:F13)<5,"",B13&"-"&C13&"-"&D13&"-"&E13&"-"&F13)
A14: 10 | B14: 4 | C14: 3 | D14: 2 | E14: 3 | F14: 4 | G14: =IF(COUNT(B14:F14)<5,"",B14&"-"&C14&"-"&D14&"-"&E14&"-"&F14)
A15: 11 | B15: 3 | C15: 2 | D15: 1 | E15: 2 | F15: 3 | G15: =IF(COUNT(B15:F15)<5,"",B15&"-"&C15&"-"&D15&"-"&E15&"-"&F15)
A16: 12 | B16: 1 | C16: 2 | D16: 1 | E16: 2 | F16: 1 | G16: =IF(COUNT(B16:F16)<5,"",B16&"-"&C16&"-"&D16&"-"&E16&"-"&F16)
... A24: 20 | B24: 1 | C24: 3 | D24: 5 | E24: 3 | F24: 1 | G24: =IF(COUNT(B24:F24)<5,"",B24&"-"&C24&"-"&D24&"-"&E24&"-"&F24)
A25: 21 | G25: =IF(COUNT(B25:F25)<5,"",B25&"-"&C25&"-"&D25&"-"&E25&"-"&F25)
A26: 22 | G26: =IF(COUNT(B26:F26)<5,"",B26&"-"&C26&"-"&D26&"-"&E26&"-"&F26)
A27: 23 | G27: =IF(COUNT(B27:F27)<5,"",B27&"-"&C27&"-"&D27&"-"&E27&"-"&F27)
A28: 24 | G28: =IF(COUNT(B28:F28)<5,"",B28&"-"&C28&"-"&D28&"-"&E28&"-"&F28)
A29: 25 | G29: =IF(COUNT(B29:F29)<5,"",B29&"-"&C29&"-"&D29&"-"&E29&"-"&F29)
A30: 26 | G30: =IF(COUNT(B30:F30)<5,"",B30&"-"&C30&"-"&D30&"-"&E30&"-"&F30)
A31: 27 | G31: =IF(COUNT(B31:F31)<5,"",B31&"-"&C31&"-"&D31&"-"&E31&"-"&F31)
A32: 28 | G32: =IF(COUNT(B32:F32)<5,"",B32&"-"&C32&"-"&D32&"-"&E32&"-"&F32)
A33: 29 | G33: =IF(COUNT(B33:F33)<5,"",B33&"-"&C33&"-"&D33&"-"&E33&"-"&F33)
A34: 30 | G34: =IF(COUNT(B34:F34)<5,"",B34&"-"&C34&"-"&D34&"-"&E34&"-"&F34)
A35: 31 | G35: =IF(COUNT(B35:F35)<5,"",B35&"-"&C35&"-"&D35&"-"&E35&"-"&F35)
A36: 32 | G36: =IF(COUNT(B36:F36)<5,"",B36&"-"&C36&"-"&D36&"-"&E36&"-"&F36)
... A54: 50 | G54: =IF(COUNT(B54:F54)<5,"",B54&"-"&C54&"-"&D54&"-"&E54&"-"&F54)

Sheet Poids
A1: Poids des symboles par rouleau
A2: Probabilité d'une case = poids / total du rouleau. À droite : probabilités calculées.
A3: JEU DE BASE
A4: Code | B4: Symbole | C4: R1 | D4: R2 | E4: R3 | F4: R4 | G4: R5 | I4: P(R1) | J4: P(R2) | K4: P(R3) | L4: P(R4) | M4: P(R5)
A5: =Paytable!A4 | B5: =Paytable!B4 | C5: 2500 | D5: 2500 | E5: 2500 | F5: 2500 | G5: 2500 | I5: =IF(C$14=0,0,C5/C$14) | J5: =IF(D$14=0,0,D5/D$14) | K5: =IF(E$14=0,0,E5/E$14) | L5: =IF(F$14=0,0,F5/F$14) | M5: =IF(G$14=0,0,G5/G$14)
A6: =Paytable!A5 | B6: =Paytable!B5 | C6: 3800 | D6: 3800 | E6: 3800 | F6: 3800 | G6: 3800 | I6: =IF(C$14=0,0,C6/C$14) | J6: =IF(D$14=0,0,D6/D$14) | K6: =IF(E$14=0,0,E6/E$14) | L6: =IF(F$14=0,0,F6/F$14) | M6: =IF(G$14=0,0,G6/G$14)
A7: =Paytable!A6 | B7: =Paytable!B6 | C7: 5200 | D7: 5200 | E7: 5200 | F7: 5200 | G7: 5200 | I7: =IF(C$14=0,0,C7/C$14) | J7: =IF(D$14=0,0,D7/D$14) | K7: =IF(E$14=0,0,E7/E$14) | L7: =IF(F$14=0,0,F7/F$14) | M7: =IF(G$14=0,0,G7/G$14)
A8: =Paytable!A7 | B8: =Paytable!B7 | C8: 7500 | D8: 7500 | E8: 7500 | F8: 7500 | G8: 7500 | I8: =IF(C$14=0,0,C8/C$14) | J8: =IF(D$14=0,0,D8/D$14) | K8: =IF(E$14=0,0,E8/E$14) | L8: =IF(F$14=0,0,F8/F$14) | M8: =IF(G$14=0,0,G8/G$14)
A9: =Paytable!A8 | B9: =Paytable!B8 | C9: 12500 | D9: 12500 | E9: 12500 | F9: 12500 | G9: 12500 | I9: =IF(C$14=0,0,C9/C$14) | J9: =IF(D$14=0,0,D9/D$14) | K9: =IF(E$14=0,0,E9/E$14) | L9: =IF(F$14=0,0,F9/F$14) | M9: =IF(G$14=0,0,G9/G$14)
A10: =Paytable!A9 | B10: =Paytable!B9 | C10: 14000 | D10: 14000 | E10: 14000 | F10: 14000 | G10: 14000 | I10: =IF(C$14=0,0,C10/C$14) | J10: =IF(D$14=0,0,D10/D$14) | K10: =IF(E$14=0,0,E10/E$14) | L10: =IF(F$14=0,0,F10/F$14) | M10: =IF(G$14=0,0,G10/G$14)
A11: =Paytable!A10 | B11: =Paytable!B10 | C11: 15500 | D11: 15500 | E11: 15500 | F11: 15500 | G11: 15500 | I11: =IF(C$14=0,0,C11/C$14) | J11: =IF(D$14=0,0,D11/D$14) | K11: =IF(E$14=0,0,E11/E$14) | L11: =IF(F$14=0,0,F11/F$14) | M11: =IF(G$14=0,0,G11/G$14)
A12: =Paytable!A11 | B12: =Paytable!B11 | C12: 940 | D12: 940 | E12: 940 | F12: 940 | G12: 940 | I12: =IF(C$14=0,0,C12/C$14) | J12: =IF(D$14=0,0,D12/D$14) | K12: =IF(E$14=0,0,E12/E$14) | L12: =IF(F$14=0,0,F12/F$14) | M12: =IF(G$14=0,0,G12/G$14)
A13: =Paytable!A12 | B13: =Paytable!B12 | C13: 2 | D13: 2 | E13: 2 | F13: 2 | G13: 2 | I13: =IF(C$14=0,0,C13/C$14) | J13: =IF(D$14=0,0,D13/D$14) | K13: =IF(E$14=0,0,E13/E$14) | L13: =IF(F$14=0,0,F13/F$14) | M13: =IF(G$14=0,0,G13/G$14)
B14: Total | C14: =SUM(C5:C13) | D14: =SUM(D5:D13) | E14: =SUM(E5:E13) | F14: =SUM(F5:F13) | G14: =SUM(G5:G13) | I14: =SUM(I5:I13) | J14: =SUM(J5:J13) | K14: =SUM(K5:K13) | L14: =SUM(L5:L13) | M14: =SUM(M5:M13)
A17: SPINS BOOSTÉS (plus de symboles bonus ; prix dans Config)
A18: Code | B18: Symbole | C18: R1 | D18: R2 | E18: R3 | F18: R4 | G18: R5 | I18: P(R1) | J18: P(R2) | K18: P(R3) | L18: P(R4) | M18: P(R5)
A19: =Paytable!A4 | B19: =Paytable!B4 | C19: 2500 | D19: 2500 | E19: 2500 | F19: 2500 | G19: 2500 | I19: =IF(C$28=0,0,C19/C$28) | J19: =IF(D$28=0,0,D19/D$28) | K19: =IF(E$28=0,0,E19/E$28) | L19: =IF(F$28=0,0,F19/F$28) | M19: =IF(G$28=0,0,G19/G$28)
A20: =Paytable!A5 | B20: =Paytable!B5 | C20: 3800 | D20: 3800 | E20: 3800 | F20: 3800 | G20: 3800 | I20: =IF(C$28=0,0,C20/C$28) | J20: =IF(D$28=0,0,D20/D$28) | K20: =IF(E$28=0,0,E20/E$28) | L20: =IF(F$28=0,0,F20/F$28) | M20: =IF(G$28=0,0,G20/G$28)
A21: =Paytable!A6 | B21: =Paytable!B6 | C21: 5200 | D21: 5200 | E21: 5200 | F21: 5200 | G21: 5200 | I21: =IF(C$28=0,0,C21/C$28) | J21: =IF(D$28=0,0,D21/D$28) | K21: =IF(E$28=0,0,E21/E$28) | L21: =IF(F$28=0,0,F21/F$28) | M21: =IF(G$28=0,0,G21/G$28)
A22: =Paytable!A7 | B22: =Paytable!B7 | C22: 7500 | D22: 7500 | E22: 7500 | F22: 7500 | G22: 7500 | I22: =IF(C$28=0,0,C22/C$28) | J22: =IF(D$28=0,0,D22/D$28) | K22: =IF(E$28=0,0,E22/E$28) | L22: =IF(F$28=0,0,F22/F$28) | M22: =IF(G$28=0,0,G22/G$28)
A23: =Paytable!A8 | B23: =Paytable!B8 | C23: 12500 | D23: 12500 | E23: 12500 | F23: 12500 | G23: 12500 | I23: =IF(C$28=0,0,C23/C$28) | J23: =IF(D$28=0,0,D23/D$28) | K23: =IF(E$28=0,0,E23/E$28) | L23: =IF(F$28=0,0,F23/F$28) | M23: =IF(G$28=0,0,G23/G$28)
A24: =Paytable!A9 | B24: =Paytable!B9 | C24: 14000 | D24: 14000 | E24: 14000 | F24: 14000 | G24: 14000 | I24: =IF(C$28=0,0,C24/C$28) | J24: =IF(D$28=0,0,D24/D$28) | K24: =IF(E$28=0,0,E24/E$28) | L24: =IF(F$28=0,0,F24/F$28) | M24: =IF(G$28=0,0,G24/G$28)
A25: =Paytable!A10 | B25: =Paytable!B10 | C25: 15500 | D25: 15500 | E25: 15500 | F25: 15500 | G25: 15500 | I25: =IF(C$28=0,0,C25/C$28) | J25: =IF(D$28=0,0,D25/D$28) | K25: =IF(E$28=0,0,E25/E$28) | L25: =IF(F$28=0,0,F25/F$28) | M25: =IF(G$28=0,0,G25/G$28)
A26: =Paytable!A11 | B26: =Paytable!B11 | C26: 1135 | D26: 1135 | E26: 1135 | F26: 1135 | G26: 1135 | I26: =IF(C$28=0,0,C26/C$28) | J26: =IF(D$28=0,0,D26/D$28) | K26: =IF(E$28=0,0,E26/E$28) | L26: =IF(F$28=0,0,F26/F$28) | M26: =IF(G$28=0,0,G26/G$28)
A27: =Paytable!A12 | B27: =Paytable!B12 | C27: 2 | D27: 2 | E27: 2 | F27: 2 | G27: 2 | I27: =IF(C$28=0,0,C27/C$28) | J27: =IF(D$28=0,0,D27/D$28) | K27: =IF(E$28=0,0,E27/E$28) | L27: =IF(F$28=0,0,F27/F$28) | M27: =IF(G$28=0,0,G27/G$28)
B28: Total | C28: =SUM(C19:C27) | D28: =SUM(D19:D27) | E28: =SUM(E19:E27) | F28: =SUM(F19:F27) | G28: =SUM(G19:G27) | I28: =SUM(I19:I27) | J28: =SUM(J19:J27) | K28: =SUM(K19:K27) | L28: =SUM(L19:L27) | M28: =SUM(M19:M27)
A31: FREE SPINS DU BONUS 1 (Free spins)
A32: Code | B32: Symbole | C32: R1 | D32: R2 | E32: R3 | F32: R4 | G32: R5 | I32: P(R1) | J32: P(R2) | K32: P(R3) | L32: P(R4) | M32: P(R5)
A33: =Paytable!A4 | B33: =Paytable!B4 | C33: 2500 | D33: 2500 | E33: 2500 | F33: 2500 | G33: 2500 | I33: =IF(C$42=0,0,C33/C$42) | J33: =IF(D$42=0,0,D33/D$42) | K33: =IF(E$42=0,0,E33/E$42) | L33: =IF(F$42=0,0,F33/F$42) | M33: =IF(G$42=0,0,G33/G$42)
A34: =Paytable!A5 | B34: =Paytable!B5 | C34: 3800 | D34: 3800 | E34: 3800 | F34: 3800 | G34: 3800 | I34: =IF(C$42=0,0,C34/C$42) | J34: =IF(D$42=0,0,D34/D$42) | K34: =IF(E$42=0,0,E34/E$42) | L34: =IF(F$42=0,0,F34/F$42) | M34: =IF(G$42=0,0,G34/G$42)
A35: =Paytable!A6 | B35: =Paytable!B6 | C35: 5200 | D35: 5200 | E35: 5200 | F35: 5200 | G35: 5200 | I35: =IF(C$42=0,0,C35/C$42) | J35: =IF(D$42=0,0,D35/D$42) | K35: =IF(E$42=0,0,E35/E$42) | L35: =IF(F$42=0,0,F35/F$42) | M35: =IF(G$42=0,0,G35/G$42)
A36: =Paytable!A7 | B36: =Paytable!B7 | C36: 7500 | D36: 7500 | E36: 7500 | F36: 7500 | G36: 7500 | I36: =IF(C$42=0,0,C36/C$42) | J36: =IF(D$42=0,0,D36/D$42) | K36: =IF(E$42=0,0,E36/E$42) | L36: =IF(F$42=0,0,F36/F$42) | M36: =IF(G$42=0,0,G36/G$42)
A37: =Paytable!A8 | B37: =Paytable!B8 | C37: 12500 | D37: 12500 | E37: 12500 | F37: 12500 | G37: 12500 | I37: =IF(C$42=0,0,C37/C$42) | J37: =IF(D$42=0,0,D37/D$42) | K37: =IF(E$42=0,0,E37/E$42) | L37: =IF(F$42=0,0,F37/F$42) | M37: =IF(G$42=0,0,G37/G$42)
A38: =Paytable!A9 | B38: =Paytable!B9 | C38: 14000 | D38: 14000 | E38: 14000 | F38: 14000 | G38: 14000 | I38: =IF(C$42=0,0,C38/C$42) | J38: =IF(D$42=0,0,D38/D$42) | K38: =IF(E$42=0,0,E38/E$42) | L38: =IF(F$42=0,0,F38/F$42) | M38: =IF(G$42=0,0,G38/G$42)
A39: =Paytable!A10 | B39: =Paytable!B10 | C39: 15500 | D39: 15500 | E39: 15500 | F39: 15500 | G39: 15500 | I39: =IF(C$42=0,0,C39/C$42) | J39: =IF(D$42=0,0,D39/D$42) | K39: =IF(E$42=0,0,E39/E$42) | L39: =IF(F$42=0,0,F39/F$42) | M39: =IF(G$42=0,0,G39/G$42)
A40: =Paytable!A11 | B40: =Paytable!B11 | C40: 1400 | D40: 1400 | E40: 1400 | F40: 1400 | G40: 1400 | I40: =IF(C$42=0,0,C40/C$42) | J40: =IF(D$42=0,0,D40/D$42) | K40: =IF(E$42=0,0,E40/E$42) | L40: =IF(F$42=0,0,F40/F$42) | M40: =IF(G$42=0,0,G40/G$42)
A41: =Paytable!A12 | B41: =Paytable!B12 | C41: 9 | D41: 9 | E41: 9 | F41: 9 | G41: 9 | I41: =IF(C$42=0,0,C41/C$42) | J41: =IF(D$42=0,0,D41/D$42) | K41: =IF(E$42=0,0,E41/E$42) | L41: =IF(F$42=0,0,F41/F$42) | M41: =IF(G$42=0,0,G41/G$42)
B42: Total | C42: =SUM(C33:C41) | D42: =SUM(D33:D41) | E42: =SUM(E33:E41) | F42: =SUM(F33:F41) | G42: =SUM(G33:G41) | I42: =SUM(I33:I41) | J42: =SUM(J33:J41) | K42: =SUM(K33:K41) | L42: =SUM(L33:L41) | M42: =SUM(M33:M41)
A45: FREE SPINS DU BONUS 2 (Super free spins)
A46: Code | B46: Symbole | C46: R1 | D46: R2 | E46: R3 | F46: R4 | G46: R5 | I46: P(R1) | J46: P(R2) | K46: P(R3) | L46: P(R4) | M46: P(R5)
...

Sheet Multis
A1: Multiplicateurs qui apparaissent autour du globe
A2: Chaque case voisine d'un globe reçoit une valeur tirée selon ces poids.
A4: Valeur | B4: Poids base / boost | C4: Poids bonus 1 | D4: Poids bonus 2 | E4: Poids bonus 3 | F4: P base / boost | G4: P bonus 1 | H4: P bonus 2 | I4: P bonus 3
A5: 1 | B5: 300 | C5: 150 | D5: 60 | E5: 500 | F5: =IF($B$14=0,0,B5/$B$14) | G5: =IF($C$14=0,0,C5/$C$14) | H5: =IF($D$14=0,0,D5/$D$14) | I5: =IF($E$14=0,0,E5/$E$14)
A6: 2 | B6: 400 | C6: 300 | D6: 200 | E6: 350 | F6: =IF($B$14=0,0,B6/$B$14) | G6: =IF($C$14=0,0,C6/$C$14) | H6: =IF($D$14=0,0,D6/$D$14) | I6: =IF($E$14=0,0,E6/$E$14)
A7: 3 | B7: 200 | C7: 250 | D7: 250 | E7: 120 | F7: =IF($B$14=0,0,B7/$B$14) | G7: =IF($C$14=0,0,C7/$C$14) | H7: =IF($D$14=0,0,D7/$D$14) | I7: =IF($E$14=0,0,E7/$E$14)
A8: 4 | B8: 60 | C8: 120 | D8: 160 | E8: 25 | F8: =IF($B$14=0,0,B8/$B$14) | G8: =IF($C$14=0,0,C8/$C$14) | H8: =IF($D$14=0,0,D8/$D$14) | I8: =IF($E$14=0,0,E8/$E$14)
A9: 5 | B9: 30 | C9: 90 | D9: 130 | E9: 5 | F9: =IF($B$14=0,0,B9/$B$14) | G9: =IF($C$14=0,0,C9/$C$14) | H9: =IF($D$14=0,0,D9/$D$14) | I9: =IF($E$14=0,0,E9/$E$14)
A10: 10 | B10: 8 | C10: 50 | D10: 80 | E10: 0 | F10: =IF($B$14=0,0,B10/$B$14) | G10: =IF($C$14=0,0,C10/$C$14) | H10: =IF($D$14=0,0,D10/$D$14) | I10: =IF($E$14=0,0,E10/$E$14)
A11: 20 | B11: 2 | C11: 20 | D11: 35 | E11: 0 | F11: =IF($B$14=0,0,B11/$B$14) | G11: =IF($C$14=0,0,C11/$C$14) | H11: =IF($D$14=0,0,D11/$D$14) | I11: =IF($E$14=0,0,E11/$E$14)
A12: 50 | B12: 0 | C12: 5 | D12: 10 | E12: 0 | F12: =IF($B$14=0,0,B12/$B$14) | G12: =IF($C$14=0,0,C12/$C$14) | H12: =IF($D$14=0,0,D12/$D$14) | I12: =IF($E$14=0,0,E12/$E$14)
A13: 100 | B13: 0 | C13: 0 | D13: 2 | E13: 0 | F13: =IF($B$14=0,0,B13/$B$14) | G13: =IF($C$14=0,0,C13/$C$14) | H13: =IF($D$14=0,0,D13/$D$14) | I13: =IF($E$14=0,0,E13/$E$14)
A14: Total | B14: =SUM(B5:B13) | C14: =SUM(C5:C13) | D14: =SUM(D5:D13) | E14: =SUM(E5:E13) | F14: =SUM(F5:F13) | G14: =SUM(G5:G13) | H14: =SUM(H5:H13) | I14: =SUM(I5:I13)
A15: Multi moyen | F15: =SUMPRODUCT($A$5:$A$13,F5:F13) | G15: =SUMPRODUCT($A$5:$A$13,G5:G13) | H15: =SUMPRODUCT($A$5:$A$13,H5:H13) | I15: =SUMPRODUCT($A$5:$A$13,I5:I13)
A17: Les spins boostés utilisent les multis du jeu de base. Les valeurs et poids sont des valeurs de départ, à ajuster.

Sheet Calc_Gains
A1: Modes LINES / WAYS seulement : RTP analytique exact HORS globe/multis (en CLUSTER, voir Simulation)
A2: WAYS : E[ways de longueur k] = Π(lignes × p_r, r ≤ k) × P(aucun sur le rouleau k+1). LINES : nb lignes × Π(p_r, r ≤ k) × (1 − p_{k+1}). Le globe et ses multis sont ajoutés par le simulateur.
A3: JEU DE BASE — RTP par spin hors globe
A4: Code | B4: Symbole | C4: p R1 | D4: p R2 | E4: p R3 | F4: p R4 | G4: p R5 | H4: E[gains 3] | I4: E[gains 4] | J4: E[gains 5] | K4: RTP (x mise) | L4: % du bloc
A5: =Paytable!A4 | B5: =Paytable!B4 | C5: =Poids!I5 | D5: =Poids!J5 | E5: =Poids!K5 | F5: =Poids!L5 | G5: =Poids!M5 | H5: =IF(MODE_GAIN="WAYS",NB_LIGNES^3*C5*D5*E5*((1-NB_LIGNES*Poids!$L$12)*(1-F5/(1-Poids!$L$12))^NB_LIGNES+NB_LIGNES*Poids!$L$12*(1-F5/(1-Poids!$L$12))^(NB_LIGNES-1)),NB_PAYLINES*C5*D5*E5*(1-F5)) | I5: =IF(MODE_GAIN="WAYS",NB_LIGNES^4*C5*D5*E5*F5*((1-NB_LIGNES*Poids!$M$12)*(1-G5/(1-Poids!$M$12))^NB_LIGNES+NB_LIGNES*Poids!$M$12*(1-G5/(1-Poids!$M$12))^(NB_LIGNES-1)),NB_PAYLINES*C5*D5*E5*F5*(1-G5)) | J5: =IF(MODE_GAIN="WAYS",NB_LIGNES^5,NB_PAYLINES)*C5*D5*E5*F5*G5 | K5: =Paytable!D4*H5+Paytable!E4*I5+Paytable!F4*J5 | L5: =IF($K$12=0,0,K5/$K$12)
A6: =Paytable!A5 | B6: =Paytable!B5 | C6: =Poids!I6 | D6: =Poids!J6 | E6: =Poids!K6 | F6: =Poids!L6 | G6: =Poids!M6 | H6: =IF(MODE_GAIN="WAYS",NB_LIGNES^3*C6*D6*E6*((1-NB_LIGNES*Poids!$L$12)*(1-F6/(1-Poids!$L$12))^NB_LIGNES+NB_LIGNES*Poids!$L$12*(1-F6/(1-Poids!$L$12))^(NB_LIGNES-1)),NB_PAYLINES*C6*D6*E6*(1-F6)) | I6: =IF(MODE_GAIN="WAYS",NB_LIGNES^4*C6*D6*E6*F6*((1-NB_LIGNES*Poids!$M$12)*(1-G6/(1-Poids!$M$12))^NB_LIGNES+NB_LIGNES*Poids!$M$12*(1-G6/(1-Poids!$M$12))^(NB_LIGNES-1)),NB_PAYLINES*C6*D6*E6*F6*(1-G6)) | J6: =IF(MODE_GAIN="WAYS",NB_LIGNES^5,NB_PAYLINES)*C6*D6*E6*F6*G6 | K6: =Paytable!D5*H6+Paytable!E5*I6+Paytable!F5*J6 | L6: =IF($K$12=0,0,K6/$K$12)
A7: =Paytable!A6 | B7: =Paytable!B6 | C7: =Poids!I7 | D7: =Poids!J7 | E7: =Poids!K7 | F7: =Poids!L7 | G7: =Poids!M7 | H7: =IF(MODE_GAIN="WAYS",NB_LIGNES^3*C7*D7*E7*((1-NB_LIGNES*Poids!$L$12)*(1-F7/(1-Poids!$L$12))^NB_LIGNES+NB_LIGNES*Poids!$L$12*(1-F7/(1-Poids!$L$12))^(NB_LIGNES-1)),NB_PAYLINES*C7*D7*E7*(1-F7)) | I7: =IF(MODE_GAIN="WAYS",NB_LIGNES^4*C7*D7*E7*F7*((1-NB_LIGNES*Poids!$M$12)*(1-G7/(1-Poids!$M$12))^NB_LIGNES+NB_LIGNES*Poids!$M$12*(1-G7/(1-Poids!$M$12))^(NB_LIGNES-1)),NB_PAYLINES*C7*D7*E7*F7*(1-G7)) | J7: =IF(MODE_GAIN="WAYS",NB_LIGNES^5,NB_PAYLINES)*C7*D7*E7*F7*G7 | K7: =Paytable!D6*H7+Paytable!E6*I7+Paytable!F6*J7 | L7: =IF($K$12=0,0,K7/$K$12)
A8: =Paytable!A7 | B8: =Paytable!B7 | C8: =Poids!I8 | D8: =Poids!J8 | E8: =Poids!K8 | F8: =Poids!L8 | G8: =Poids!M8 | H8: =IF(MODE_GAIN="WAYS",NB_LIGNES^3*C8*D8*E8*((1-NB_LIGNES*Poids!$L$12)*(1-F8/(1-Poids!$L$12))^NB_LIGNES+NB_LIGNES*Poids!$L$12*(1-F8/(1-Poids!$L$12))^(NB_LIGNES-1)),NB_PAYLINES*C8*D8*E8*(1-F8)) | I8: =IF(MODE_GAIN="WAYS",NB_LIGNES^4*C8*D8*E8*F8*((1-NB_LIGNES*Poids!$M$12)*(1-G8/(1-Poids!$M$12))^NB_LIGNES+NB_LIGNES*Poids!$M$12*(1-G8/(1-Poids!$M$12))^(NB_LIGNES-1)),NB_PAYLINES*C8*D8*E8*F8*(1-G8)) | J8: =IF(MODE_GAIN="WAYS",NB_LIGNES^5,NB_PAYLINES)*C8*D8*E8*F8*G8 | K8: =Paytable!D7*H8+Paytable!E7*I8+Paytable!F7*J8 | L8: =IF($K$12=0,0,K8/$K$12)
A9: =Paytable!A8 | B9: =Paytable!B8 | C9: =Poids!I9 | D9: =Poids!J9 | E9: =Poids!K9 | F9: =Poids!L9 | G9: =Poids!M9 | H9: =IF(MODE_GAIN="WAYS",NB_LIGNES^3*C9*D9*E9*((1-NB_LIGNES*Poids!$L$12)*(1-F9/(1-Poids!$L$12))^NB_LIGNES+NB_LIGNES*Poids!$L$12*(1-F9/(1-Poids!$L$12))^(NB_LIGNES-1)),NB_PAYLINES*C9*D9*E9*(1-F9)) | I9: =IF(MODE_GAIN="WAYS",NB_LIGNES^4*C9*D9*E9*F9*((1-NB_LIGNES*Poids!$M$12)*(1-G9/(1-Poids!$M$12))^NB_LIGNES+NB_LIGNES*Poids!$M$12*(1-G9/(1-Poids!$M$12))^(NB_LIGNES-1)),NB_PAYLINES*C9*D9*E9*F9*(1-G9)) | J9: =IF(MODE_GAIN="WAYS",NB_LIGNES^5,NB_PAYLINES)*C9*D9*E9*F9*G9 | K9: =Paytable!D8*H9+Paytable!E8*I9+Paytable!F8*J9 | L9: =IF($K$12=0,0,K9/$K$12)
A10: =Paytable!A9 | B10: =Paytable!B9 | C10: =Poids!I10 | D10: =Poids!J10 | E10: =Poids!K10 | F10: =Poids!L10 | G10: =Poids!M10 | H10: =IF(MODE_GAIN="WAYS",NB_LIGNES^3*C10*D10*E10*((1-NB_LIGNES*Poids!$L$12)*(1-F10/(1-Poids!$L$12))^NB_LIGNES+NB_LIGNES*Poids!$L$12*(1-F10/(1-Poids!$L$12))^(NB_LIGNES-1)),NB_PAYLINES*C10*D10*E10*(1-F10)) | I10: =IF(MODE_GAIN="WAYS",NB_LIGNES^4*C10*D10*E10*F10*((1-NB_LIGNES*Poids!$M$12)*(1-G10/(1-Poids!$M$12))^NB_LIGNES+NB_LIGNES*Poids!$M$12*(1-G10/(1-Poids!$M$12))^(NB_LIGNES-1)),NB_PAYLINES*C10*D10*E10*F10*(1-G10)) | J10: =IF(MODE_GAIN="WAYS",NB_LIGNES^5,NB_PAYLINES)*C10*D10*E10*F10*G10 | K10: =Paytable!D9*H10+Paytable!E9*I10+Paytable!F9*J10 | L10: =IF($K$12=0,0,K10/$K$12)
A11: =Paytable!A10 | B11: =Paytable!B10 | C11: =Poids!I11 | D11: =Poids!J11 | E11: =Poids!K11 | F11: =Poids!L11 | G11: =Poids!M11 | H11: =IF(MODE_GAIN="WAYS",NB_LIGNES^3*C11*D11*E11*((1-NB_LIGNES*Poids!$L$12)*(1-F11/(1-Poids!$L$12))^NB_LIGNES+NB_LIGNES*Poids!$L$12*(1-F11/(1-Poids!$L$12))^(NB_LIGNES-1)),NB_PAYLINES*C11*D11*E11*(1-F11)) | I11: =IF(MODE_GAIN="WAYS",NB_LIGNES^4*C11*D11*E11*F11*((1-NB_LIGNES*Poids!$M$12)*(1-G11/(1-Poids!$M$12))^NB_LIGNES+NB_LIGNES*Poids!$M$12*(1-G11/(1-Poids!$M$12))^(NB_LIGNES-1)),NB_PAYLINES*C11*D11*E11*F11*(1-G11)) | J11: =IF(MODE_GAIN="WAYS",NB_LIGNES^5,NB_PAYLINES)*C11*D11*E11*F11*G11 | K11: =Paytable!D10*H11+Paytable!E10*I11+Paytable!F10*J11 | L11: =IF($K$12=0,0,K11/$K$12)
B12: Total | H12: =SUM(H5:H11) | I12: =SUM(I5:I11) | J12: =SUM(J5:J11) | K12: =SUM(K5:K11) | L12: =SUM(L5:L11)
A15: FREE SPINS DU BONUS 1 — gain moyen par FS hors globe (x mise)
A16: Code | B16: Symbole | C16: p R1 | D16: p R2 | E16: p R3 | F16: p R4 | G16: p R5 | H16: E[gains 3] | I16: E[gains 4] | J16: E[gains 5] | K16: RTP (x mise) | L16: % du bloc
A17: =Paytable!A4 | B17: =Paytable!B4 | C17: =Poids!I33 | D17: =Poids!J33 | E17: =Poids!K33 | F17: =Poids!L33 | G17: =Poids!M33 | H17: =IF(MODE_GAIN="WAYS",NB_LIGNES^3*C17*D17*E17*((1-NB_LIGNES*Poids!$L$40)*(1-F17/(1-Poids!$L$40))^NB_LIGNES+NB_LIGNES*Poids!$L$40*(1-F17/(1-Poids!$L$40))^(NB_LIGNES-1)),NB_PAYLINES*C17*D17*E17*(1-F17)) | I17: =IF(MODE_GAIN="WAYS",NB_LIGNES^4*C17*D17*E17*F17*((1-NB_LIGNES*Poids!$M$40)*(1-G17/(1-Poids!$M$40))^NB_LIGNES+NB_LIGNES*Poids!$M$40*(1-G17/(1-Poids!$M$40))^(NB_LIGNES-1)),NB_PAYLINES*C17*D17*E17*F17*(1-G17)) | J17: =IF(MODE_GAIN="WAYS",NB_LIGNES^5,NB_PAYLINES)*C17*D17*E17*F17*G17 | K17: =Paytable!D4*H17+Paytable!E4*I17+Paytable!F4*J17 | L17: =IF($K$24=0,0,K17/$K$24)
A18: =Paytable!A5 | B18: =Paytable!B5 | C18: =Poids!I34 | D18: =Poids!J34 | E18: =Poids!K34 | F18: =Poids!L34 | G18: =Poids!M34 | H18: =IF(MODE_GAIN="WAYS",NB_LIGNES^3*C18*D18*E18*((1-NB_LIGNES*Poids!$L$40)*(1-F18/(1-Poids!$L$40))^NB_LIGNES+NB_LIGNES*Poids!$L$40*(1-F18/(1-Poids!$L$40))^(NB_LIGNES-1)),NB_PAYLINES*C18*D18*E18*(1-F18)) | I18: =IF(MODE_GAIN="WAYS",NB_LIGNES^4*C18*D18*E18*F18*((1-NB_LIGNES*Poids!$M$40)*(1-G18/(1-Poids!$M$40))^NB_LIGNES+NB_LIGNES*Poids!$M$40*(1-G18/(1-Poids!$M$40))^(NB_LIGNES-1)),NB_PAYLINES*C18*D18*E18*F18*(1-G18)) | J18: =IF(MODE_GAIN="WAYS",NB_LIGNES^5,NB_PAYLINES)*C18*D18*E18*F18*G18 | K18: =Paytable!D5*H18+Paytable!E5*I18+Paytable!F5*J18 | L18: =IF($K$24=0,0,K18/$K$24)
A19: =Paytable!A6 | B19: =Paytable!B6 | C19: =Poids!I35 | D19: =Poids!J35 | E19: =Poids!K35 | F19: =Poids!L35 | G19: =Poids!M35 | H19: =IF(MODE_GAIN="WAYS",NB_LIGNES^3*C19*D19*E19*((1-NB_LIGNES*Poids!$L$40)*(1-F19/(1-Poids!$L$40))^NB_LIGNES+NB_LIGNES*Poids!$L$40*(1-F19/(1-Poids!$L$40))^(NB_LIGNES-1)),NB_PAYLINES*C19*D19*E19*(1-F19)) | I19: =IF(MODE_GAIN="WAYS",NB_LIGNES^4*C19*D19*E19*F19*((1-NB_LIGNES*Poids!$M$40)*(1-G19/(1-Poids!$M$40))^NB_LIGNES+NB_LIGNES*Poids!$M$40*(1-G19/(1-Poids!$M$40))^(NB_LIGNES-1)),NB_PAYLINES*C19*D19*E19*F19*(1-G19)) | J19: =IF(MODE_GAIN="WAYS",NB_LIGNES^5,NB_PAYLINES)*C19*D19*E19*F19*G19 | K19: =Paytable!D6*H19+Paytable!E6*I19+Paytable!F6*J19 | L19: =IF($K$24=0,0,K19/$K$24)
A20: =Paytable!A7 | B20: =Paytable!B7 | C20: =Poids!I36 | D20: =Poids!J36 | E20: =Poids!K36 | F20: =Poids!L36 | G20: =Poids!M36 | H20: =IF(MODE_GAIN="WAYS",NB_LIGNES^3*C20*D20*E20*((1-NB_LIGNES*Poids!$L$40)*(1-F20/(1-Poids!$L$40))^NB_LIGNES+NB_LIGNES*Poids!$L$40*(1-F20/(1-Poids!$L$40))^(NB_LIGNES-1)),NB_PAYLINES*C20*D20*E20*(1-F20)) | I20: =IF(MODE_GAIN="WAYS",NB_LIGNES^4*C20*D20*E20*F20*((1-NB_LIGNES*Poids!$M$40)*(1-G20/(1-Poids!$M$40))^NB_LIGNES+NB_LIGNES*Poids!$M$40*(1-G20/(1-Poids!$M$40))^(NB_LIGNES-1)),NB_PAYLINES*C20*D20*E20*F20*(1-G20)) | J20: =IF(MODE_GAIN="WAYS",NB_LIGNES^5,NB_PAYLINES)*C20*D20*E20*F20*G20 | K20: =Paytable!D7*H20+Paytable!E7*I20+Paytable!F7*J20 | L20: =IF($K$24=0,0,K20/$K$24)
A21: =Paytable!A8 | B21: =Paytable!B8 | C21: =Poids!I37 | D21: =Poids!J37 | E21: =Poids!K37 | F21: =Poids!L37 | G21: =Poids!M37 | H21: =IF(MODE_GAIN="WAYS",NB_LIGNES^3*C21*D21*E21*((1-NB_LIGNES*Poids!$L$40)*(1-F21/(1-Poids!$L$40))^NB_LIGNES+NB_LIGNES*Poids!$L$40*(1-F21/(1-Poids!$L$40))^(NB_LIGNES-1)),NB_PAYLINES*C21*D21*E21*(1-F21)) | I21: =IF(MODE_GAIN="WAYS",NB_LIGNES^4*C21*D21*E21*F21*((1-NB_LIGNES*Poids!$M$40)*(1-G21/(1-Poids!$M$40))^NB_LIGNES+NB_LIGNES*Poids!$M$40*(1-G21/(1-Poids!$M$40))^(NB_LIGNES-1)),NB_PAYLINES*C21*D21*E21*F21*(1-G21)) | J21: =IF(MODE_GAIN="WAYS",NB_LIGNES^5,NB_PAYLINES)*C21*D21*E21*F21*G21 | K21: =Paytable!D8*H21+Paytable!E8*I21+Paytable!F8*J21 | L21: =IF($K$24=0,0,K21/$K$24)
A22: =Paytable!A9 | B22: =Paytable!B9 | C22: =Poids!I38 | D22: =Poids!J38 | E22: =Poids!K38 | F22: =Poids!L38 | G22: =Poids!M38 | H22: =IF(MODE_GAIN="WAYS",NB_LIGNES^3*C22*D22*E22*((1-NB_LIGNES*Poids!$L$40)*(1-F22/(1-Poids!$L$40))^NB_LIGNES+NB_LIGNES*Poids!$L$40*(1-F22/(1-Poids!$L$40))^(NB_LIGNES-1)),NB_PAYLINES*C22*D22*E22*(1-F22)) | I22: =IF(MODE_GAIN="WAYS",NB_LIGNES^4*C22*D22*E22*F22*((1-NB_LIGNES*Poids!$M$40)*(1-G22/(1-Poids!$M$40))^NB_LIGNES+NB_LIGNES*Poids!$M$40*(1-G22/(1-Poids!$M$40))^(NB_LIGNES-1)),NB_PAYLINES*C22*D22*E22*F22*(1-G22)) | J22: =IF(MODE_GAIN="WAYS",NB_LIGNES^5,NB_PAYLINES)*C22*D22*E22*F22*G22 | K22: =Paytable!D9*H22+Paytable!E9*I22+Paytable!F9*J22 | L22: =IF($K$24=0,0,K22/$K$24)
A23: =Paytable!A10 | B23: =Paytable!B10 | C23: =Poids!I39 | D23: =Poids!J39 | E23: =Poids!K39 | F23: =Poids!L39 | G23: =Poids!M39 | H23: =IF(MODE_GAIN="WAYS",NB_LIGNES^3*C23*D23*E23*((1-NB_LIGNES*Poids!$L$40)*(1-F23/(1-Poids!$L$40))^NB_LIGNES+NB_LIGNES*Poids!$L$40*(1-F23/(1-Poids!$L$40))^(NB_LIGNES-1)),NB_PAYLINES*C23*D23*E23*(1-F23)) | I23: =IF(MODE_GAIN="WAYS",NB_LIGNES^4*C23*D23*E23*F23*((1-NB_LIGNES*Poids!$M$40)*(1-G23/(1-Poids!$M$40))^NB_LIGNES+NB_LIGNES*Poids!$M$40*(1-G23/(1-Poids!$M$40))^(NB_LIGNES-1)),NB_PAYLINES*C23*D23*E23*F23*(1-G23)) | J23: =IF(MODE_GAIN="WAYS",NB_LIGNES^5,NB_PAYLINES)*C23*D23*E23*F23*G23 | K23: =Paytable!D10*H23+Paytable!E10*I23+Paytable!F10*J23 | L23: =IF($K$24=0,0,K23/$K$24)
B24: Total | H24: =SUM(H17:H23) | I24: =SUM(I17:I23) | J24: =SUM(J17:J23) | K24: =SUM(K17:K23) | L24: =SUM(L17:L23)
A26: Contrôle : mets le poids du Globe à 0 dans Poids, relance le simulateur. Le RTP de base simulé doit être égal au total ci-dessus.

Sheet Calc_Bonus
A1: Fréquence des bonus, nombre de FS, fréquence du globe
A2: Au plus 1 symbole bonus par rouleau sur la grille de départ (probabilité = lignes × p). Sans les cascades, qui en ajoutent (voir Simulation).
A3: Probabilité d'une case
A4: Symbole / phase | B4: R1 | C4: R2 | D4: R3 | E4: R4 | F4: R5
A5: Symbole bonus — base | B5: =Poids!I12 | C5: =Poids!J12 | D5: =Poids!K12 | E5: =Poids!L12 | F5: =Poids!M12
A6: Symbole bonus — boost | B6: =Poids!I26 | C6: =Poids!J26 | D6: =Poids!K26 | E6: =Poids!L26 | F6: =Poids!M26
A7: Symbole bonus — FS bonus 1 | B7: =Poids!I40 | C7: =Poids!J40 | D7: =Poids!K40 | E7: =Poids!L40 | F7: =Poids!M40
A8: Symbole bonus — FS bonus 2 | B8: =Poids!I54 | C8: =Poids!J54 | D8: =Poids!K54 | E8: =Poids!L54 | F8: =Poids!M54
A9: Symbole bonus — FS bonus 3 | B9: =Poids!I68 | C9: =Poids!J68 | D9: =Poids!K68 | E9: =Poids!L68 | F9: =Poids!M68
A10: Globe — base | B10: =Poids!I13 | C10: =Poids!J13 | D10: =Poids!K13 | E10: =Poids!L13 | F10: =Poids!M13
A11: Globe — boost | B11: =Poids!I27 | C11: =Poids!J27 | D11: =Poids!K27 | E11: =Poids!L27 | F11: =Poids!M27
A12: Globe — FS bonus 1 | B12: =Poids!I41 | C12: =Poids!J41 | D12: =Poids!K41 | E12: =Poids!L41 | F12: =Poids!M41
A13: Globe — FS bonus 2 | B13: =Poids!I55 | C13: =Poids!J55 | D13: =Poids!K55 | E13: =Poids!L55 | F13: =Poids!M55
A14: Globe — FS bonus 3 | B14: =Poids!I69 | C14: =Poids!J69 | D14: =Poids!K69 | E14: =Poids!L69 | F14: =Poids!M69
A16: Nombre de symboles bonus sur la grille de départ (au plus 1 par rouleau, comme sur les bandes du SDK)
A17: n | B17: base R1 | C17: base R1–2 | D17: base R1–3 | E17: base R1–4 | F17: base R1–5 | G17: boost R1 | H17: boost R1–2 | I17: boost R1–3 | J17: boost R1–4 | K17: boost R1–5
A18: 0 | B18: =IF($A18=0,1-MIN(1,NB_LIGNES*B$5),IF($A18=1,MIN(1,NB_LIGNES*B$5),0)) | C18: =B18*(1-MIN(1,NB_LIGNES*C$5)) | D18: =C18*(1-MIN(1,NB_LIGNES*D$5)) | E18: =D18*(1-MIN(1,NB_LIGNES*E$5)) | F18: =E18*(1-MIN(1,NB_LIGNES*F$5)) | G18: =IF($A18=0,1-MIN(1,NB_LIGNES*B$6),IF($A18=1,MIN(1,NB_LIGNES*B$6),0)) | H18: =G18*(1-MIN(1,NB_LIGNES*C$6)) | I18: =H18*(1-MIN(1,NB_LIGNES*D$6)) | J18: =I18*(1-MIN(1,NB_LIGNES*E$6)) | K18: =J18*(1-MIN(1,NB_LIGNES*F$6))
A19: 1 | B19: =IF($A19=0,1-MIN(1,NB_LIGNES*B$5),IF($A19=1,MIN(1,NB_LIGNES*B$5),0)) | C19: =B19*(1-MIN(1,NB_LIGNES*C$5))+B18*MIN(1,NB_LIGNES*C$5) | D19: =C19*(1-MIN(1,NB_LIGNES*D$5))+C18*MIN(1,NB_LIGNES*D$5) | E19: =D19*(1-MIN(1,NB_LIGNES*E$5))+D18*MIN(1,NB_LIGNES*E$5) | F19: =E19*(1-MIN(1,NB_LIGNES*F$5))+E18*MIN(1,NB_LIGNES*F$5) | G19: =IF($A19=0,1-MIN(1,NB_LIGNES*B$6),IF($A19=1,MIN(1,NB_LIGNES*B$6),0)) | H19: =G19*(1-MIN(1,NB_LIGNES*C$6))+G18*MIN(1,NB_LIGNES*C$6) | I19: =H19*(1-MIN(1,NB_LIGNES*D$6))+H18*MIN(1,NB_LIGNES*D$6) | J19: =I19*(1-MIN(1,NB_LIGNES*E$6))+I18*MIN(1,NB_LIGNES*E$6) | K19: =J19*(1-MIN(1,NB_LIGNES*F$6))+J18*MIN(1,NB_LIGNES*F$6)
A20: 2 | B20: =IF($A20=0,1-MIN(1,NB_LIGNES*B$5),IF($A20=1,MIN(1,NB_LIGNES*B$5),0)) | C20: =B20*(1-MIN(1,NB_LIGNES*C$5))+B19*MIN(1,NB_LIGNES*C$5) | D20: =C20*(1-MIN(1,NB_LIGNES*D$5))+C19*MIN(1,NB_LIGNES*D$5) | E20: =D20*(1-MIN(1,NB_LIGNES*E$5))+D19*MIN(1,NB_LIGNES*E$5) | F20: =E20*(1-MIN(1,NB_LIGNES*F$5))+E19*MIN(1,NB_LIGNES*F$5) | G20: =IF($A20=0,1-MIN(1,NB_LIGNES*B$6),IF($A20=1,MIN(1,NB_LIGNES*B$6),0)) | H20: =G20*(1-MIN(1,NB_LIGNES*C$6))+G19*MIN(1,NB_LIGNES*C$6) | I20: =H20*(1-MIN(1,NB_LIGNES*D$6))+H19*MIN(1,NB_LIGNES*D$6) | J20: =I20*(1-MIN(1,NB_LIGNES*E$6))+I19*MIN(1,NB_LIGNES*E$6) | K20: =J20*(1-MIN(1,NB_LIGNES*F$6))+J19*MIN(1,NB_LIGNES*F$6)
A21: 3 | B21: =IF($A21=0,1-MIN(1,NB_LIGNES*B$5),IF($A21=1,MIN(1,NB_LIGNES*B$5),0)) | C21: =B21*(1-MIN(1,NB_LIGNES*C$5))+B20*MIN(1,NB_LIGNES*C$5) | D21: =C21*(1-MIN(1,NB_LIGNES*D$5))+C20*MIN(1,NB_LIGNES*D$5) | E21: =D21*(1-MIN(1,NB_LIGNES*E$5))+D20*MIN(1,NB_LIGNES*E$5) | F21: =E21*(1-MIN(1,NB_LIGNES*F$5))+E20*MIN(1,NB_LIGNES*F$5) | G21: =IF($A21=0,1-MIN(1,NB_LIGNES*B$6),IF($A21=1,MIN(1,NB_LIGNES*B$6),0)) | H21: =G21*(1-MIN(1,NB_LIGNES*C$6))+G20*MIN(1,NB_LIGNES*C$6) | I21: =H21*(1-MIN(1,NB_LIGNES*D$6))+H20*MIN(1,NB_LIGNES*D$6) | J21: =I21*(1-MIN(1,NB_LIGNES*E$6))+I20*MIN(1,NB_LIGNES*E$6) | K21: =J21*(1-MIN(1,NB_LIGNES*F$6))+J20*MIN(1,NB_LIGNES*F$6)
A22: 4 | B22: =IF($A22=0,1-MIN(1,NB_LIGNES*B$5),IF($A22=1,MIN(1,NB_LIGNES*B$5),0)) | C22: =B22*(1-MIN(1,NB_LIGNES*C$5))+B21*MIN(1,NB_LIGNES*C$5) | D22: =C22*(1-MIN(1,NB_LIGNES*D$5))+C21*MIN(1,NB_LIGNES*D$5) | E22: =D22*(1-MIN(1,NB_LIGNES*E$5))+D21*MIN(1,NB_LIGNES*E$5) | F22: =E22*(1-MIN(1,NB_LIGNES*F$5))+E21*MIN(1,NB_LIGNES*F$5) | G22: =IF($A22=0,1-MIN(1,NB_LIGNES*B$6),IF($A22=1,MIN(1,NB_LIGNES*B$6),0)) | H22: =G22*(1-MIN(1,NB_LIGNES*C$6))+G21*MIN(1,NB_LIGNES*C$6) | I22: =H22*(1-MIN(1,NB_LIGNES*D$6))+H21*MIN(1,NB_LIGNES*D$6) | J22: =I22*(1-MIN(1,NB_LIGNES*E$6))+I21*MIN(1,NB_LIGNES*E$6) | K22: =J22*(1-MIN(1,NB_LIGNES*F$6))+J21*MIN(1,NB_LIGNES*F$6)
A23: 5 | B23: =IF($A23=0,1-MIN(1,NB_LIGNES*B$5),IF($A23=1,MIN(1,NB_LIGNES*B$5),0)) | C23: =B23*(1-MIN(1,NB_LIGNES*C$5))+B22*MIN(1,NB_LIGNES*C$5) | D23: =C23*(1-MIN(1,NB_LIGNES*D$5))+C22*MIN(1,NB_LIGNES*D$5) | E23: =D23*(1-MIN(1,NB_LIGNES*E$5))+D22*MIN(1,NB_LIGNES*E$5) | F23: =E23*(1-MIN(1,NB_LIGNES*F$5))+E22*MIN(1,NB_LIGNES*F$5) | G23: =IF($A23=0,1-MIN(1,NB_LIGNES*B$6),IF($A23=1,MIN(1,NB_LIGNES*B$6),0)) | H23: =G23*(1-MIN(1,NB_LIGNES*C$6))+G22*MIN(1,NB_LIGNES*C$6) | I23: =H23*(1-MIN(1,NB_LIGNES*D$6))+H22*MIN(1,NB_LIGNES*D$6) | J23: =I23*(1-MIN(1,NB_LIGNES*E$6))+I22*MIN(1,NB_LIGNES*E$6) | K23: =J23*(1-MIN(1,NB_LIGNES*F$6))+J22*MIN(1,NB_LIGNES*F$6)
A25: Résultats
A26: Indicateur | B26: Jeu de base | C26: Spins boostés
A27: ="Bonus 1 ("&Config!A25&") : 1 spin sur" | B27: =IFERROR(1/SUMPRODUCT(--($A$18:$A$23>=Config!$B$25),--($A$18:$A$23<Config!$B$26),F18:F23),"-") | C27: =IFERROR(1/SUMPRODUCT(--($A$18:$A$23>=Config!$B$25),--($A$18:$A$23<Config!$B$26),K18:K23),"-")
A28: ="Bonus 2 ("&Config!A26&") : 1 spin sur" | B28: =IFERROR(1/SUMPRODUCT(--($A$18:$A$23>=Config!$B$26),--($A$18:$A$23<Config!$B$27),F18:F23),"-") | C28: =IFERROR(1/SUMPRODUCT(--($A$18:$A$23>=Config!$B$26),--($A$18:$A$23<Config!$B$27),K18:K23),"-")
A29: ="Bonus 3 ("&Config!A27&") : 1 spin sur" | B29: =IFERROR(1/SUMPRODUCT(--($A$18:$A$23>=Config!$B$27),--($A$18:$A$23<99),F18:F23),"-") | C29: =IFERROR(1/SUMPRODUCT(--($A$18:$A$23>=Config!$B$27),--($A$18:$A$23<99),K18:K23),"-")
A30: Tous les bonus : 1 spin sur | B30: =IFERROR(1/SUMPRODUCT(--($A$18:$A$23>=Config!$B$25),F18:F23),"-") | C30: =IFERROR(1/SUMPRODUCT(--($A$18:$A$23>=Config!$B$25),K18:K23),"-")
A32: Globe
A33: Phase | B33: Globes moyens par spin | C33: P(au moins 1 globe)
A34: base | B34: =NB_LIGNES*SUM(B10:F10) | C34: =1-(1-B10)^NB_LIGNES*(1-C10)^NB_LIGNES*(1-D10)^NB_LIGNES*(1-E10)^NB_LIGNES*(1-F10)^NB_LIGNES
A35: boost | B35: =NB_LIGNES*SUM(B11:F11) | C35: =1-(1-B11)^NB_LIGNES*(1-C11)^NB_LIGNES*(1-D11)^NB_LIGNES*(1-E11)^NB_LIGNES*(1-F11)^NB_LIGNES
A36: FS bonus 1 | B36: =NB_LIGNES*SUM(B12:F12) | C36: =IF(Config!$D$25="OUI",1,1-(1-B12)^NB_LIGNES*(1-C12)^NB_LIGNES*(1-D12)^NB_LIGNES*(1-E12)^NB_LIGNES*(1-F12)^NB_LIGNES)
A37: FS bonus 2 | B37: =NB_LIGNES*SUM(B13:F13) | C37: =IF(Config!$D$26="OUI",1,1-(1-B13)^NB_LIGNES*(1-C13)^NB_LIGNES*(1-D13)^NB_LIGNES*(1-E13)^NB_LIGNES*(1-F13)^NB_LIGNES)
A38: FS bonus 3 | B38: =NB_LIGNES*SUM(B14:F14) | C38: =IF(Config!$D$27="OUI",1,1-(1-B14)^NB_LIGNES*(1-C14)^NB_LIGNES*(1-D14)^NB_LIGNES*(1-E14)^NB_LIGNES*(1-F14)^NB_LIGNES)
A40: Free spins (retrigger compris)
A41: Bonus | B41: Symboles bonus par FS (μ) | C41: FS moyens par bonus
A42: =Config!A25 | B42: =NB_LIGNES*SUM(B7:F7) | C42: =IF(B42*FS_PAR_BONUS>=1,"Infini (μ ≥ 1)",Config!C25/(1-B42*FS_PAR_BONUS))
A43: =Config!A26 | B43: =NB_LIGNES*SUM(B8:F8) | C43: =IF(B43*FS_PAR_BONUS>=1,"Infini (μ ≥ 1)",Config!C26/(1-B43*FS_PAR_BONUS))
A44: =Config!A27 | B44: =NB_LIGNES*SUM(B9:F9) | C44: =IF(B44*FS_PAR_BONUS>=1,"Infini (μ ≥ 1)",Config!C27/(1-B44*FS_PAR_BONUS))
...

Sheet Simulation
A1: Résultats du simulateur (écrits par simulateur.py — ne pas saisir ici)
A2: Relance : python simulateur.py modele_maths.xlsx. Les lignes « P(départ … → bonus …) » servent à l'export vers le SDK.
A4: Indicateur | B4: Jeu de base | C4: Spins boostés | F4: Distribution des gains par tour | G4: Jeu de base | H4: Spins boostés
A5: Date de la simulation | B5: 2026-10-09 22:32 | C5: 2026-10-09 22:32 | F5: 0 x | G5: 0.69961927 | H5: 0.7007893
A6: Spins simulés | B6: 3078340 | C6: 1535082 | F6: 0 – 1 x | G6: 0.18027035 | H6: 0.1784256
A7: Coût d'un spin (x mise) | B7: 1 | C7: 1.25 | F7: 1 – 5 x | G7: 0.11078456 | H7: 0.10891918
A8: RTP des spins (hors bonus) | B8: 0.58880305 | C8: 0.46458061 | F8: 5 – 20 x | G8: 0.007767981 | H8: 0.0098339719
A9: RTP des bonus | B9: 0.35686423 | C9: 0.51970127 | F9: 20 – 100 x | G9: 0.00054806051 | H9: 0.00072930807
A10: RTP total | B10: 0.94566728 | C10: 0.98428188 | F10: 100 – 1000 x | G10: 0.0008623815 | H10: 0.0010639761
A11: Marge d'erreur RTP (± à 95 %) | B11: 0.02212876 | C11: 0.035951893 | F11: 1000 x – max win | G11: 0.00014737504 | H11: 0.00023865434
A12: Hit frequency | B12: 0.30038073 | C12: 0.2992107 | F12: Max win atteint | G12: 2.0421557e-08 | H12: 2.1074004e-08
A13: Écart-type par tour (x mise) | B13: 24.624859 | C13: 33.314725
A14: Bonus (tous) : 1 spin sur | B14: 180.86112 | C14: 108.10913
A15: Bonus 1 : 1 spin sur | B15: 191.61759 | C15: 116.07268
A16: Bonus 2 : 1 spin sur | B16: 3344.7131 | C16: 1657.9121
A17: Bonus 3 : 1 spin sur | B17: 87738.897 | C17: 31793.727
A18: Bonus 1 : gain moyen (x mise) | B18: 56.033372 | C18: 58.086078
A19: Bonus 2 : gain moyen (x mise) | B19: 151.49355 | C19: 146.40518
A20: Bonus 3 : gain moyen (x mise) | B20: 1680.0145 | C20: 1935.9558
A21: Bonus 1 : FS joués en moyenne | B21: 25.934827 | C21: 25.79775
A22: Bonus 2 : FS joués en moyenne | B22: 30.79813 | C22: 30.830427
A23: Bonus 3 : FS joués en moyenne | B23: 7.0494325 | C23: 7.0341644
A24: Max win observé (x mise) | B24: 10000 | C24: 10000
... A37: P(départ 5 symboles bonus → bonus 3) | B37: 2.5151458e-06 | C37: 6.3544493e-06
A40: Chaque bonus joué directement | B40: Bonus 1 | C40: Bonus 2 | D40: Bonus 3
A41: Sessions simulées | B41: 100000 | C41: 100000 | D41: 100000
A42: Prix d'achat (x mise) | B42: 59 | C42: 160
A43: Gain moyen (x mise) | B43: 55.574819 | C43: 154.06163 | D43: 1697.9365
A44: RTP au prix actuel | B44: 0.94194608 | C44: 0.96288519
A45: Prix conseillé (gain moyen / RTP cible) | B45: 57.890436 | C45: 160.48087 | D45: 1768.6839
A46: Gain médian (x mise) | B46: 7.6 | C46: 10 | D46: 1594.7
A47: Max win observé (x mise) | B47: 10000 | C47: 10000 | D47: 7863.4
A48: 3 étoiles : etl40b (limite 0,9) | B48: 5.375398 | C48: 4.790162
A49: 3 étoiles : etl10k (limite 0,8) | B49: 0.1 | C49: 1
A51: RTP par symbole (x mise par spin de base)
A52: Code | B52: Symbole | C52: Spins (hors bonus) | D52: Bonus
A53: H1 | B53: Premium 1 | C53: 0.029666907 | D53: 0.034323914
A54: H2 | B54: Premium 2 | C54: 0.030467119 | D54: 0.03661637
A55: H3 | B55: Premium 3 | C55: 0.032609649 | D55: 0.034966824
A56: M1 | B56: Moyen 1 | C56: 0.050015789 | D56: 0.042613174
...
